Workbook

Sheet TJKT
A1: NO | B1: KODE ASET | C1: NAMA PC | D1: PROSESOR | E1: RAM | F1: STORAGE | G1: OS | H1: KEYBOARD | I1: MOUSE | J1: MONITOR | K1: MEREK CASING | L1: KONDISI | M1: Motherboard | N1: LOKASI | O1: TAHUN PENGADAAN | P1: TANGGAL PENDATAAN | Q1: PETUGAS PENDATA | R1: FOTO | S1: CATATAN | T1: BARCODE
A2: PC 1 | B2: =CONCATENATE("TJKT-PC-00",RIGHT(A2,LEN(A2) - (FIND(" ",A2))),"-26") -> TJKT-PC-001-26 | C2: 1HGJ5PE | D2: i5-2400 | E2: 8 GB | F2: 128 GB | G2: WINDOWS 10 | H2: LOGITECH | I2: LOGITECH | J2: SAMSUNG 19 INCH | K2: DAZUMBA | L2: BAIK | M2: ASUS H61M-K | N2: LAB TJKT | O2: 2026 | P2: 1 | Q2: Joko | T2: =IMAGE("https://quickchart.io/qr?text=" & ENCODEURL("https://script.google.com/macros/s/AKfycbwUw2zru1c30d7u6vNwK6_c7tb3xEU0ZXquHJ8FWE6Y3IgmK5rEhzofiQ0rYAA2noQv/exec?id=" & B2))
A3: PC 2 | B3: =CONCATENATE("TJKT-PC-00",RIGHT(A3,LEN(A3) - (FIND(" ",A3))),"-26") -> TJKT-PC-002-26 | C3: - | D3: i5-2400 | E3: 8 GB | F3: 128 GB | G3: WINDOWS 10 | H3: LOGITECH | I3: LOGITECH | J3: SAMSUNG 19 INCH | K3: DAZUMBA | L3: MATI | M3: ASUS H61M-K | T3: =IMAGE("https://quickchart.io/qr?text="&ENCODEURL("https://script.google.com/macros/s/AKfycbzpGAZd7mcVr0PnVDexUszHll-s1iSgqFYXXfBckFPgj2khM9Ha8fOOiopWS2BJgo5U/exec?id="&B3))
A4: PC 3 | B4: =CONCATENATE("TJKT-PC-00",RIGHT(A4,LEN(A4) - (FIND(" ",A4))),"-26") -> TJKT-PC-003-26 | C4: WINDOWS-PJPV946 | D4: INTEL CORE i3-2120 | E4: 4.00 GB | F4: 119 GB | G4: WINDOWS 10 | H4: LOGITECH | I4: LOGITECH | J4: SAMSUNG 19 INC | K4: DAZUMBA | L4: BAIK | M4: INTEL COPPORATION H61 | T4: =IMAGE("https://quickchart.io/qr?text="&ENCODEURL("https://script.google.com/macros/s/AKfycbwQpzkxOCRP3NYqoeT2iICUn44Z1fFWd3SGrCOmIeLE-uz8Fxp4eBwg-OJKyc6xQgcnDA/exec?id="&B4))
A5: PC 4 | B5: =CONCATENATE("TJKT-PC-00",RIGHT(A5,LEN(A5) - (FIND(" ",A5))),"-26") -> TJKT-PC-004-26 | C5: WINDOWS-QP2DIN5 | D5: INTEL CORE i5-2400 | E5: 8.00 | F5: 112 GB | G5: WINDOWS 10 | H5: LOGITECH | I5: LOGITECH | J5: SAMSUNG 19 INC | K5: DAZUMBA | L5: BAIK | M5: ASUSTEK H61M-K | T5: =IMAGE("https://quickchart.io/qr?text="&ENCODEURL("https://script.google.com/macros/s/AKfycbwQpzkxOCRP3NYqoeT2iICUn44Z1fFWd3SGrCOmIeLE-uz8Fxp4eBwg-OJKyc6xQgcnDA/exec?id="&B5))
A6: PC 5 | B6: =CONCATENATE("TJKT-PC-00",RIGHT(A6,LEN(A6) - (FIND(" ",A6))),"-26") -> TJKT-PC-005-26 | C6: WINDOWS-5SNV95A | D6: INTEL CORE i3-2120 | E6: 4.GB | G6: WINDOWS 10 | H6: LOGITECH | I6: LOGITECH | J6: SAMSUNG 19 INC | K6: DAZUMBA | L6: BAIK | M6: INTEL COPPORATION H61 | T6: =IMAGE("https://quickchart.io/qr?text="&ENCODEURL("https://script.google.com/macros/s/AKfycbwQpzkxOCRP3NYqoeT2iICUn44Z1fFWd3SGrCOmIeLE-uz8Fxp4eBwg-OJKyc6xQgcnDA/exec?id="&B6))
A7: PC 6 | B7: =CONCATENATE("TJKT-PC-00",RIGHT(A7,LEN(A7) - (FIND(" ",A7))),"-26") -> TJKT-PC-006-26 | C7: WINDOWS-5RV5JCM | D7: INTEL CORE i3-2121 | E7: 4.GB | F7: 221 GB | G7: WINDOWS 10 | H7: LOGITECH | I7: LOGITECH | J7: SAMSUNG 19 INC | K7: FIERCE WARS | L7: BAIK | M7: GIGABYTE TECHNOLOGY H8 1M-D52 | T7: =IMAGE("https://quickchart.io/qr?text="&ENCODEURL("https://script.google.com/macros/s/AKfycbwQpzkxOCRP3NYqoeT2iICUn44Z1fFWd3SGrCOmIeLE-uz8Fxp4eBwg-OJKyc6xQgcnDA/exec?id="&B7))
A8: PC 7 | B8: =CONCATENATE("TJKT-PC-00",RIGHT(A8,LEN(A8) - (FIND(" ",A8))),"-26") -> TJKT-PC-007-26 | C8: - | D8: i3-3240 | E8: 4 GB | F8: 128 GB | G8: WINDOWS 10 | H8: LOGITECH | I8: LOGITECH | J8: LG 19 INC | K8: SIMCOOL | L8: PORT USB RUSAK | M8: GIGABYTE H61M-S2P-R3 | T8: =IMAGE("https://quickchart.io/qr?text="&ENCODEURL("https://script.google.com/macros/s/AKfycbwQpzkxOCRP3NYqoeT2iICUn44Z1fFWd3SGrCOmIeLE-uz8Fxp4eBwg-OJKyc6xQgcnDA/exec?id="&B8))
A9: PC 8 | B9: =CONCATENATE("TJKT-PC-00",RIGHT(A9,LEN(A9) - (FIND(" ",A9))),"-26") -> TJKT-PC-008-26 | C9: - | D9: - | E9: - | F9: - | G9: - | H9: - | I9: - | J9: - | K9: - | L9: GUDANG | M9: - | T9: =IMAGE("https://quickchart.io/qr?text="&ENCODEURL("https://script.google.com/macros/s/AKfycbwQpzkxOCRP3NYqoeT2iICUn44Z1fFWd3SGrCOmIeLE-uz8Fxp4eBwg-OJKyc6xQgcnDA/exec?id="&B9))
A10: PC 9 | B10: =CONCATENATE("TJKT-PC-00",RIGHT(A10,LEN(A10) - (FIND(" ",A10))),"-26") -> TJKT-PC-009-26 | C10: WINDOWS-U3L4OMR | D10: INTEL (R) PENTIUM (R) | E10: 4.00 GB | F10: 125 GB | G10: WINDOWS 10 | H10: LOGITECH | I10: LOGITECH | J10: LENOVO 19 INC | K10: SIMCOOL | L10: BAIK | M10: GIGABYTE TECHNOLOGY H61M | T10: =IMAGE("https://quickchart.io/qr?text="&ENCODEURL("https://script.google.com/macros/s/AKfycbwQpzkxOCRP3NYqoeT2iICUn44Z1fFWd3SGrCOmIeLE-uz8Fxp4eBwg-OJKyc6xQgcnDA/exec?id="&B10))
A11: PC 10 | B11: =CONCATENATE("TJKT-PC-00",RIGHT(A11,LEN(A11) - (FIND(" ",A11))),"-26") -> TJKT-PC-0010-26 | C11: WINDOWS-V52GKJV | D11: INTEL CORE i5-2500 | E11: 4.00 GB | F11: 112 GB | G11: WINDOWS 10 | H11: LOGITECH | I11: LOGITECH | J11: LENOVO 19 INC | K11: DAZUMBA | L11: BAIK | M11: ASUSTEK H61M-K | T11: =IMAGE("https://quickchart.io/qr?text="&ENCODEURL("https://script.google.com/macros/s/AKfycbwQpzkxOCRP3NYqoeT2iICUn44Z1fFWd3SGrCOmIeLE-uz8Fxp4eBwg-OJKyc6xQgcnDA/exec?id="&B11))
A12: PC 11 | B12: =CONCATENATE("TJKT-PC-00",RIGHT(A12,LEN(A12) - (FIND(" ",A12))),"-26") -> TJKT-PC-0011-26 | C12: IPL 3J00 | D12: INTEL CORE i5-2400 | E12: 8 GB | F12: 112 GB | G12: WINDOWS 10 | H12: LOGITECH | I12: LOGITECH | J12: LG 19 INC | K12: DAZUMBA | L12: BAIK | M12: ASUSTEK H61M-K | T12: =IMAGE("https://quickchart.io/qr?text="&ENCODEURL("https://script.google.com/macros/s/AKfycbwQpzkxOCRP3NYqoeT2iICUn44Z1fFWd3SGrCOmIeLE-uz8Fxp4eBwg-OJKyc6xQgcnDA/exec?id="&B12))
A13: PC 12 | B13: =CONCATENATE("TJKT-PC-00",RIGHT(A13,LEN(A13) - (FIND(" ",A13))),"-26") -> TJKT-PC-0012-26 | C13: WINDOWS-K17JJFJ | D13: INTEL CORE i3-4170 | E13: 4.00 GB | F13: 932 GB | G13: WINDOWS 10 | H13: LOGITECH | I13: LOGITECH | J13: VARRO | K13: SIMBADDA | L13: BAIK | M13: GIGABYTE H81M-D52 | T13: =IMAGE("https://quickchart.io/qr?text="&ENCODEURL("https://script.google.com/macros/s/AKfycbwQpzkxOCRP3NYqoeT2iICUn44Z1fFWd3SGrCOmIeLE-uz8Fxp4eBwg-OJKyc6xQgcnDA/exec?id="&B13))
A14: PC 13 | B14: =CONCATENATE("TJKT-PC-00",RIGHT(A14,LEN(A14) - (FIND(" ",A14))),"-26") -> TJKT-PC-0013-26 | C14: WINDOWS-HJ6G9G | D14: INTEL CORE i3-3240 | E14: 4.00 GB | F14: 112 GB | G14: WINDOWS 10 | H14: LOGITECH | I14: LOGITECH | J14: DELL | K14: SIM COOL | L14: BAIK | M14: GIGABYTE TECHNOLOGY H61M-52P-R3 | T14: =IMAGE("https://quickchart.io/qr?text="&ENCODEURL("https://script.google.com/macros/s/AKfycbwQpzkxOCRP3NYqoeT2iICUn44Z1fFWd3SGrCOmIeLE-uz8Fxp4eBwg-OJKyc6xQgcnDA/exec?id="&B14))
A15: PC 14 | B15: =CONCATENATE("TJKT-PC-00",RIGHT(A15,LEN(A15) - (FIND(" ",A15))),"-26") -> TJKT-PC-0014-26 | C15: WINDOWS-PME75HV | D15: INTEL CORE i3-3240 | E15: 4.00 GB | F15: 112 GB | G15: WINDOWS 10 | H15: LOGITECH | I15: LOGITECH | J15: DELL | K15: SIM COOL | L15: BAIK | M15: GIGABYTE H61-52PV REV 2.2 | T15: =IMAGE("https://quickchart.io/qr?text="&ENCODEURL("https://script.google.com/macros/s/AKfycbwQpzkxOCRP3NYqoeT2iICUn44Z1fFWd3SGrCOmIeLE-uz8Fxp4eBwg-OJKyc6xQgcnDA/exec?id="&B15))
A16: PC 15 | B16: =CONCATENATE("TJKT-PC-00",RIGHT(A16,LEN(A16) - (FIND(" ",A16))),"-26") -> TJKT-PC-0015-26 | C16: - | D16: i3-2120 | E16: 4 GB | F16: 128 | G16: WINDOWS 10 | H16: LOGITECH | I16: LOGITECH | J16: DELL 14 INCH | K16: POWER LOQIC | L16: WINDOWS ERROR | M16: BIOSTAR H61MLV3 | T16: =IMAGE("https://quickchart.io/qr?text="&ENCODEURL("https://script.google.com/macros/s/AKfycbwQpzkxOCRP3NYqoeT2iICUn44Z1fFWd3SGrCOmIeLE-uz8Fxp4eBwg-OJKyc6xQgcnDA/exec?id="&B16))
A17: PC 16 | B17: =CONCATENATE("TJKT-PC-00",RIGHT(A17,LEN(A17) - (FIND(" ",A17))),"-26") -> TJKT-PC-0016-26 | C17: WINDOWS-67V25RT | D17: INTEL CORE i5-2400 | E17: 12.00 GB | F17: 112 GB | G17: WINDOWS 10 | H17: LOGITECH | I17: LOGITECH | J17: SAMSUNG 19 INC | K17: DAZUMBA | L17: BAIK | M17: ASUSTEK H61M-K | T17: =IMAGE("https://quickchart.io/qr?text="&ENCODEURL("https://script.google.com/macros/s/AKfycbwQpzkxOCRP3NYqoeT2iICUn44Z1fFWd3SGrCOmIeLE-uz8Fxp4eBwg-OJKyc6xQgcnDA/exec?id="&B17))
A18: PC 17 | B18: =CONCATENATE("TJKT-PC-00",RIGHT(A18,LEN(A18) - (FIND(" ",A18))),"-26") -> TJKT-PC-0017-26 | C18: WINDOWS-TQTO7FE | D18: INTEL CORE i5-2400 | E18: 8.00 GB | F18: 112 GB | G18: WINDOWS 10 | H18: LOGITECH | I18: LOGITECH | J18: DELL | K18: DAZUMBA | L18: BAIK | M18: ASUSTEK H61M-K | T18: =IMAGE("https://quickchart.io/qr?text="&ENCODEURL("https://script.google.com/macros/s/AKfycbwQpzkxOCRP3NYqoeT2iICUn44Z1fFWd3SGrCOmIeLE-uz8Fxp4eBwg-OJKyc6xQgcnDA/exec?id="&B18))
A19: PC 18 | B19: =CONCATENATE("TJKT-PC-00",RIGHT(A19,LEN(A19) - (FIND(" ",A19))),"-26") -> TJKT-PC-0018-26 | C19: DUGVTGD | D19: INTEL CORE i3-2120 | E19: 6 GB | F19: 466 GB | G19: WINDOWS 10 | H19: LOGITECH | I19: LOGITECH | J19: ACER 14 INC | K19: POWER LOQIC | L19: BAIK | M19: BIOSTAR H61MLV3 | T19: =IMAGE("https://quickchart.io/qr?text="&ENCODEURL("https://script.google.com/macros/s/AKfycbwQpzkxOCRP3NYqoeT2iICUn44Z1fFWd3SGrCOmIeLE-uz8Fxp4eBwg-OJKyc6xQgcnDA/exec?id="&B19))
A20: PC 19 | B20: =CONCATENATE("TJKT-PC-00",RIGHT(A20,LEN(A20) - (FIND(" ",A20))),"-26") -> TJKT-PC-0019-26 | C20: K5501LG | D20: INTEL CORE i3 | E20: 4.00 GB | F20: 112 GB | G20: WINDOWS 10 | H20: LOGITECH | I20: LOGITECH | J20: LG 19 INC | K20: SIM COOL | L20: BAIK | M20: GIGABYTE TECHNOLOGI H 81M-D52 | T20: =IMAGE("https://quickchart.io/qr?text="&ENCODEURL("https://script.google.com/macros/s/AKfycbwQpzkxOCRP3NYqoeT2iICUn44Z1fFWd3SGrCOmIeLE-uz8Fxp4eBwg-OJKyc6xQgcnDA/exec?id="&B20))
A21: PC 20 | B21: =CONCATENATE("TJKT-PC-00",RIGHT(A21,LEN(A21) - (FIND(" ",A21))),"-26") -> TJKT-PC-0020-26 | C21: WINDOWS-QLRDHBE | D21: INTEL CORE i5-6500 | E21: 16 GB | F21: 477 GB | G21: WINDOWS 10 | H21: LOGITECH | I21: LOGITECH | J21: SAMSUNG 19 INC | K21: TIDAK ADA | L21: BAIK | M21: ASUS H 110MM-K | T21: =IMAGE("https://quickchart.io/qr?text="&ENCODEURL("https://script.google.com/macros/s/AKfycbwQpzkxOCRP3NYqoeT2iICUn44Z1fFWd3SGrCOmIeLE-uz8Fxp4eBwg-OJKyc6xQgcnDA/exec?id="&B21))
A22: PC 21 | B22: =CONCATENATE("TJKT-PC-00",RIGHT(A22,LEN(A22) - (FIND(" ",A22))),"-26") -> TJKT-PC-0021-26 | C22: WINDOWS-DLBLH58 | D22: INTEL CORE i3-4170 | E22: 4.00 GB | F22: 585 GB | G22: WINDOWS 10 | H22: LOGITECH | I22: LOGITECH | J22: LENOVO 19 INC | K22: SIMCOOL | L22: BAIK | M22: GIGABYTE TEVHNOLOGI H81M-D52 | T22: =IMAGE("https://quickchart.io/qr?text="&ENCODEURL("https://script.google.com/macros/s/AKfycbwQpzkxOCRP3NYqoeT2iICUn44Z1fFWd3SGrCOmIeLE-uz8Fxp4eBwg-OJKyc6xQgcnDA/exec?id="&B22))
A23: PC 22 | B23: =CONCATENATE("TJKT-PC-00",RIGHT(A23,LEN(A23) - (FIND(" ",A23))),"-26") -> TJKT-PC-0022-26 | C23: - | D23: - | E23: - | F23: - | G23: - | H23: - | I23: - | J23: - | K23: - | L23: GUDANG | M23: - | T23: =IMAGE("https://quickchart.io/qr?text="&ENCODEURL("https://script.google.com/macros/s/AKfycbwQpzkxOCRP3NYqoeT2iICUn44Z1fFWd3SGrCOmIeLE-uz8Fxp4eBwg-OJKyc6xQgcnDA/exec?id="&B23))
A24: PC 23 | B24: =CONCATENATE("TJKT-PC-00",RIGHT(A24,LEN(A24) - (FIND(" ",A24))),"-26") -> TJKT-PC-0023-26 | C24: - | D24: - | E24: - | F24: - | G24: - | H24: - | I24: - | J24: - | K24: - | L24: GUDANG | M24: - | T24: =IMAGE("https://quickchart.io/qr?text="&ENCODEURL("https://script.google.com/macros/s/AKfycbwQpzkxOCRP3NYqoeT2iICUn44Z1fFWd3SGrCOmIeLE-uz8Fxp4eBwg-OJKyc6xQgcnDA/exec?id="&B24))
A25: PC 24 | B25: =CONCATENATE("TJKT-PC-00",RIGHT(A25,LEN(A25) - (FIND(" ",A25))),"-26") -> TJKT-PC-0024-26 | C25: - | D25: i3-2120 | E25: 4 GB | F25: 500 GB | G25: WINDOWS 10 | H25: LOGITECH | I25: LOGITECH | J25: DELL 14 INCH | K25: POWER LOQIC | L25: WINDOWS ERROR | M25: BIOSTAR H61MLV3 | T25: =IMAGE("https://quickchart.io/qr?text="&ENCODEURL("https://script.google.com/macros/s/AKfycbwQpzkxOCRP3NYqoeT2iICUn44Z1fFWd3SGrCOmIeLE-uz8Fxp4eBwg-OJKyc6xQgcnDA/exec?id="&B25))
A26: PC 25 | B26: =CONCATENATE("TJKT-PC-00",RIGHT(A26,LEN(A26) - (FIND(" ",A26))),"-26") -> TJKT-PC-0025-26 | C26: DEKSTOP-VGKGQ4F | D26: INTEL CORE i3-2120 | E26: 4.00 GB | F26: 477 GB | G26: WINDOWS 10 | H26: LOGITECH | I26: LOGITECH | J26: LENOVO 19 INC | K26: AVARIS | L26: BAIK | M26: INTEL CORPORATION H61 | T26: =IMAGE("https://quickchart.io/qr?text="&ENCODEURL("https://script.google.com/macros/s/AKfycbwQpzkxOCRP3NYqoeT2iICUn44Z1fFWd3SGrCOmIeLE-uz8Fxp4eBwg-OJKyc6xQgcnDA/exec?id="&B26))
A27: PC 26 | B27: =CONCATENATE("TJKT-PC-00",RIGHT(A27,LEN(A27) - (FIND(" ",A27))),"-26") -> TJKT-PC-0026-26 | C27: 4VKJBTR | D27: i3-4170 | E27: 4 GB | F27: 500 GB | G27: WINDOWS 10 | H27: LOGITECH | I27: LOGITECH | J27: LG 19 INC | K27: SIMBADDA | L27: BAIK | M27: GIGABYTE H81M-D52 | T27: =IMAGE("https://quickchart.io/qr?text="&ENCODEURL("https://script.google.com/macros/s/AKfycbwQpzkxOCRP3NYqoeT2iICUn44Z1fFWd3SGrCOmIeLE-uz8Fxp4eBwg-OJKyc6xQgcnDA/exec?id="&B27))
A28: PC 27 | B28: =CONCATENATE("TJKT-PC-00",RIGHT(A28,LEN(A28) - (FIND(" ",A28))),"-26") -> TJKT-PC-0027-26 | C28: U08H62F | D28: INTEL CORE i3-4170 | E28: 4.00 GB | F28: 585 GB | G28: WINDOWS 10 | H28: DELL | I28: DELL | J28: ACER 14 INC | K28: SIMBADDA | L28: BAIK | M28: GIGABYTE TECHNOLOGI H 81M-D52 | T28: =IMAGE("https://quickchart.io/qr?text="&ENCODEURL("https://script.google.com/macros/s/AKfycbwQpzkxOCRP3NYqoeT2iICUn44Z1fFWd3SGrCOmIeLE-uz8Fxp4eBwg-OJKyc6xQgcnDA/exec?id="&B28))
... A36: PC 35 | B36: =CONCATENATE("TJKT-PC-00",RIGHT(A36,LEN(A36) - (FIND(" ",A36))),"-26") -> TJKT-PC-0035-26 | C36: IQ4ONO6 | D36: i3-2120 | E36: 4 GB | F36: 128 GB | G36: WINDOWS 10 | H36: LOGITECH | I36: LOGITECH | J36: LENOVO 19 INC | K36: AVARIS | L36: BAIK | M36: INTEL H61 | T36: =IMAGE("https://quickchart.io/qr?text="&ENCODEURL("https://script.google.com/macros/s/AKfycbwQpzkxOCRP3NYqoeT2iICUn44Z1fFWd3SGrCOmIeLE-uz8Fxp4eBwg-OJKyc6xQgcnDA/exec?id="&B36))

Sheet BARCODE TJKT
A1: =TJKT!T2 | B1: =TJKT!T3 | C1: =TJKT!T4 | D1: =TJKT!T4 | E1: =TJKT!T5 | F1: {=IFERROR(INDEX(TJKT!$T:$T, (ROUNDUP(ROW()/2,0)-1)*7 + COLUMN() + 1), "")} | G1: {=IFERROR(INDEX(TJKT!$T:$T, (ROUNDUP(ROW()/2,0)-1)*7 + COLUMN() + 1), "")}
A2: {=IFERROR(INDEX(TJKT!$B:$B, (ROW()/2-1)*7 + COLUMN() + 1), "")} -> TJKT-PC-001-26 | B2: {=IFERROR(INDEX(TJKT!$B:$B, (ROW()/2-1)*7 + COLUMN() + 1), "")} -> TJKT-PC-002-26 | C2: {=IFERROR(INDEX(TJKT!$B:$B, (ROW()/2-1)*7 + COLUMN() + 1), "")} -> TJKT-PC-003-26 | D2: {=IFERROR(INDEX(TJKT!$B:$B, (ROW()/2-1)*7 + COLUMN() + 1), "")} -> TJKT-PC-004-26 | E2: {=IFERROR(INDEX(TJKT!$B:$B, (ROW()/2-1)*7 + COLUMN() + 1), "")} -> TJKT-PC-005-26 | F2: {=IFERROR(INDEX(TJKT!$B:$B, (ROW()/2-1)*7 + COLUMN() + 1), "")} -> TJKT-PC-006-26 | G2: {=IFERROR(INDEX(TJKT!$B:$B, (ROW()/2-1)*7 + COLUMN() + 1), "")} -> TJKT-PC-007-26
A3: {=IFERROR(INDEX(TJKT!$T:$T, (ROUNDUP(ROW()/2,0)-1)*7 + COLUMN() + 1), "")} | B3: {=IFERROR(INDEX(TJKT!$T:$T, (ROUNDUP(ROW()/2,0)-1)*7 + COLUMN() + 1), "")} | C3: {=IFERROR(INDEX(TJKT!$T:$T, (ROUNDUP(ROW()/2,0)-1)*7 + COLUMN() + 1), "")} | D3: {=IFERROR(INDEX(TJKT!$T:$T, (ROUNDUP(ROW()/2,0)-1)*7 + COLUMN() + 1), "")} | E3: {=IFERROR(INDEX(TJKT!$T:$T, (ROUNDUP(ROW()/2,0)-1)*7 + COLUMN() + 1), "")} | F3: {=IFERROR(INDEX(TJKT!$T:$T, (ROUNDUP(ROW()/2,0)-1)*7 + COLUMN() + 1), "")} | G3: {=IFERROR(INDEX(TJKT!$T:$T, (ROUNDUP(ROW()/2,0)-1)*7 + COLUMN() + 1), "")}
A4: {=IFERROR(INDEX(TJKT!$B:$B, (ROW()/2-1)*7 + COLUMN() + 1), "")} -> TJKT-PC-008-26 | B4: {=IFERROR(INDEX(TJKT!$B:$B, (ROW()/2-1)*7 + COLUMN() + 1), "")} -> TJKT-PC-009-26 | C4: {=IFERROR(INDEX(TJKT!$B:$B, (ROW()/2-1)*7 + COLUMN() + 1), "")} -> TJKT-PC-0010-26 | D4: {=IFERROR(INDEX(TJKT!$B:$B, (ROW()/2-1)*7 + COLUMN() + 1), "")} -> TJKT-PC-0011-26 | E4: {=IFERROR(INDEX(TJKT!$B:$B, (ROW()/2-1)*7 + COLUMN() + 1), "")} -> TJKT-PC-0012-26 | F4: {=IFERROR(INDEX(TJKT!$B:$B, (ROW()/2-1)*7 + COLUMN() + 1), "")} -> TJKT-PC-0013-26 | G4: {=IFERROR(INDEX(TJKT!$B:$B, (ROW()/2-1)*7 + COLUMN() + 1), "")} -> TJKT-PC-0014-26
A5: {=IFERROR(INDEX(TJKT!$T:$T, (ROUNDUP(ROW()/2,0)-1)*7 + COLUMN() + 1), "")} | B5: {=IFERROR(INDEX(TJKT!$T:$T, (ROUNDUP(ROW()/2,0)-1)*7 + COLUMN() + 1), "")} | C5: {=IFERROR(INDEX(TJKT!$T:$T, (ROUNDUP(ROW()/2,0)-1)*7 + COLUMN() + 1), "")} | D5: {=IFERROR(INDEX(TJKT!$T:$T, (ROUNDUP(ROW()/2,0)-1)*7 + COLUMN() + 1), "")} | E5: {=IFERROR(INDEX(TJKT!$T:$T, (ROUNDUP(ROW()/2,0)-1)*7 + COLUMN() + 1), "")} | F5: {=IFERROR(INDEX(TJKT!$T:$T, (ROUNDUP(ROW()/2,0)-1)*7 + COLUMN() + 1), "")} | G5: {=IFERROR(INDEX(TJKT!$T:$T, (ROUNDUP(ROW()/2,0)-1)*7 + COLUMN() + 1), "")}
A6: {=IFERROR(INDEX(TJKT!$B:$B, (ROW()/2-1)*7 + COLUMN() + 1), "")} -> TJKT-PC-0015-26 | B6: {=IFERROR(INDEX(TJKT!$B:$B, (ROW()/2-1)*7 + COLUMN() + 1), "")} -> TJKT-PC-0016-26 | C6: {=IFERROR(INDEX(TJKT!$B:$B, (ROW()/2-1)*7 + COLUMN() + 1), "")} -> TJKT-PC-0017-26 | D6: {=IFERROR(INDEX(TJKT!$B:$B, (ROW()/2-1)*7 + COLUMN() + 1), "")} -> TJKT-PC-0018-26 | E6: {=IFERROR(INDEX(TJKT!$B:$B, (ROW()/2-1)*7 + COLUMN() + 1), "")} -> TJKT-PC-0019-26 | F6: {=IFERROR(INDEX(TJKT!$B:$B, (ROW()/2-1)*7 + COLUMN() + 1), "")} -> TJKT-PC-0020-26 | G6: {=IFERROR(INDEX(TJKT!$B:$B, (ROW()/2-1)*7 + COLUMN() + 1), "")} -> TJKT-PC-0021-26
A7: {=IFERROR(INDEX(TJKT!$T:$T, (ROUNDUP(ROW()/2,0)-1)*7 + COLUMN() + 1), "")} | B7: {=IFERROR(INDEX(TJKT!$T:$T, (ROUNDUP(ROW()/2,0)-1)*7 + COLUMN() + 1), "")} | C7: {=IFERROR(INDEX(TJKT!$T:$T, (ROUNDUP(ROW()/2,0)-1)*7 + COLUMN() + 1), "")} | D7: {=IFERROR(INDEX(TJKT!$T:$T, (ROUNDUP(ROW()/2,0)-1)*7 + COLUMN() + 1), "")} | E7: {=IFERROR(INDEX(TJKT!$T:$T, (ROUNDUP(ROW()/2,0)-1)*7 + COLUMN() + 1), "")} | F7: {=IFERROR(INDEX(TJKT!$T:$T, (ROUNDUP(ROW()/2,0)-1)*7 + COLUMN() + 1), "")} | G7: {=IFERROR(INDEX(TJKT!$T:$T, (ROUNDUP(ROW()/2,0)-1)*7 + COLUMN() + 1), "")}
A8: {=IFERROR(INDEX(TJKT!$B:$B, (ROW()/2-1)*7 + COLUMN() + 1), "")} -> TJKT-PC-0022-26 | B8: {=IFERROR(INDEX(TJKT!$B:$B, (ROW()/2-1)*7 + COLUMN() + 1), "")} -> TJKT-PC-0023-26 | C8: {=IFERROR(INDEX(TJKT!$B:$B, (ROW()/2-1)*7 + COLUMN() + 1), "")} -> TJKT-PC-0024-26 | D8: {=IFERROR(INDEX(TJKT!$B:$B, (ROW()/2-1)*7 + COLUMN() + 1), "")} -> TJKT-PC-0025-26 | E8: {=IFERROR(INDEX(TJKT!$B:$B, (ROW()/2-1)*7 + COLUMN() + 1), "")} -> TJKT-PC-0026-26 | F8: {=IFERROR(INDEX(TJKT!$B:$B, (ROW()/2-1)*7 + COLUMN() + 1), "")} -> TJKT-PC-0027-26 | G8: {=IFERROR(INDEX(TJKT!$B:$B, (ROW()/2-1)*7 + COLUMN() + 1), "")} -> TJKT-PC-0028-26
A9: {=IFERROR(INDEX(TJKT!$T:$T, (ROUNDUP(ROW()/2,0)-1)*7 + COLUMN() + 1), "")} | B9: {=IFERROR(INDEX(TJKT!$T:$T, (ROUNDUP(ROW()/2,0)-1)*7 + COLUMN() + 1), "")} | C9: {=IFERROR(INDEX(TJKT!$T:$T, (ROUNDUP(ROW()/2,0)-1)*7 + COLUMN() + 1), "")} | D9: {=IFERROR(INDEX(TJKT!$T:$T, (ROUNDUP(ROW()/2,0)-1)*7 + COLUMN() + 1), "")} | E9: {=IFERROR(INDEX(TJKT!$T:$T, (ROUNDUP(ROW()/2,0)-1)*7 + COLUMN() + 1), "")} | F9: {=IFERROR(INDEX(TJKT!$T:$T, (ROUNDUP(ROW()/2,0)-1)*7 + COLUMN() + 1), "")} | G9: {=IFERROR(INDEX(TJKT!$T:$T, (ROUNDUP(ROW()/2,0)-1)*7 + COLUMN() + 1), "")}
A10: {=IFERROR(INDEX(TJKT!$B:$B, (ROW()/2-1)*7 + COLUMN() + 1), "")} -> TJKT-PC-0029-26 | B10: {=IFERROR(INDEX(TJKT!$B:$B, (ROW()/2-1)*7 + COLUMN() + 1), "")} -> TJKT-PC-0030-26 | C10: {=IFERROR(INDEX(TJKT!$B:$B, (ROW()/2-1)*7 + COLUMN() + 1), "")} -> TJKT-PC-0031-26 | D10: {=IFERROR(INDEX(TJKT!$B:$B, (ROW()/2-1)*7 + COLUMN() + 1), "")} -> TJKT-PC-0032-26 | E10: {=IFERROR(INDEX(TJKT!$B:$B, (ROW()/2-1)*7 + COLUMN() + 1), "")} -> TJKT-PC-0033-26 | F10: {=IFERROR(INDEX(TJKT!$B:$B, (ROW()/2-1)*7 + COLUMN() + 1), "")} -> TJKT-PC-0034-26 | G10: {=IFERROR(INDEX(TJKT!$B:$B, (ROW()/2-1)*7 + COLUMN() + 1), "")} -> TJKT-PC-0035-26
A11: {=IFERROR(INDEX(TJKT!$T:$T, (ROUNDUP(ROW()/2,0)-1)*7 + COLUMN() + 1), "")} | B11: {=IFERROR(INDEX(TJKT!$T:$T, (ROUNDUP(ROW()/2,0)-1)*7 + COLUMN() + 1), "")} | C11: {=IFERROR(INDEX(TJKT!$T:$T, (ROUNDUP(ROW()/2,0)-1)*7 + COLUMN() + 1), "")} | D11: {=IFERROR(INDEX(TJKT!$T:$T, (ROUNDUP(ROW()/2,0)-1)*7 + COLUMN() + 1), "")} | E11: {=IFERROR(INDEX(TJKT!$T:$T, (ROUNDUP(ROW()/2,0)-1)*7 + COLUMN() + 1), "")} | F11: {=IFERROR(INDEX(TJKT!$T:$T, (ROUNDUP(ROW()/2,0)-1)*7 + COLUMN() + 1), "")} | G11: {=IFERROR(INDEX(TJKT!$T:$T, (ROUNDUP(ROW()/2,0)-1)*7 + COLUMN() + 1), "")}
A12: {=IFERROR(INDEX(TJKT!$B:$B, (ROW()/2-1)*7 + COLUMN() + 1), "")} | B12: {=IFERROR(INDEX(TJKT!$B:$B, (ROW()/2-1)*7 + COLUMN() + 1), "")} | C12: {=IFERROR(INDEX(TJKT!$B:$B, (ROW()/2-1)*7 + COLUMN() + 1), "")} | D12: {=IFERROR(INDEX(TJKT!$B:$B, (ROW()/2-1)*7 + COLUMN() + 1), "")} | E12: {=IFERROR(INDEX(TJKT!$B:$B, (ROW()/2-1)*7 + COLUMN() + 1), "")} | F12: {=IFERROR(INDEX(TJKT!$B:$B, (ROW()/2-1)*7 + COLUMN() + 1), "")} | G12: {=IFERROR(INDEX(TJKT!$B:$B, (ROW()/2-1)*7 + COLUMN() + 1), "")}
A13: {=IFERROR(INDEX(TJKT!$T:$T, (ROUNDUP(ROW()/2,0)-1)*7 + COLUMN() + 1), "")} | B13: {=IFERROR(INDEX(TJKT!$T:$T, (ROUNDUP(ROW()/2,0)-1)*7 + COLUMN() + 1), "")} | C13: {=IFERROR(INDEX(TJKT!$T:$T, (ROUNDUP(ROW()/2,0)-1)*7 + COLUMN() + 1), "")} | D13: {=IFERROR(INDEX(TJKT!$T:$T, (ROUNDUP(ROW()/2,0)-1)*7 + COLUMN() + 1), "")} | E13: {=IFERROR(INDEX(TJKT!$T:$T, (ROUNDUP(ROW()/2,0)-1)*7 + COLUMN() + 1), "")} | F13: {=IFERROR(INDEX(TJKT!$T:$T, (ROUNDUP(ROW()/2,0)-1)*7 + COLUMN() + 1), "")} | G13: {=IFERROR(INDEX(TJKT!$T:$T, (ROUNDUP(ROW()/2,0)-1)*7 + COLUMN() + 1), "")}

Sheet MPLB
A1: NO | B1: KODE ASET | C1: NAMA PC | D1: PROSESOR | E1: RAM | F1: STORAGE | G1: OS | H1: KEYBOARD | I1: MOUSE | J1: MONITOR | K1: MEREK CASING | L1: KONDISI | M1: Motherboard | N1: LOKASI | O1: TAHUN PENGADAAN | P1: TANGGAL PENDATAAN | Q1: PETUGAS PENDATA | R1: FOTO | S1: CATATAN | T1: BARCODE
A2: PC 1 | B2: =CONCATENATE("MPLB-PC-00",RIGHT(A2,LEN(A2) - (FIND(" ",A2))),"-26") -> MPLB-PC-001-26 | C2: - | D2: INTEL CORE i5-3470 | E2: 8 GB | F2: 500 GB | G2: WINDOWS 10 | H2: LOGITECH | I2: LOGITECH | J2: LG 19 INCH | K2: SIMBADDA | L2: MONITOR MATI | M2: ASUSTEK H61M-K | T2: =IMAGE("https://quickchart.io/qr?text="&ENCODEURL("https://script.google.com/macros/s/AKfycbwQpzkxOCRP3NYqoeT2iICUn44Z1fFWd3SGrCOmIeLE-uz8Fxp4eBwg-OJKyc6xQgcnDA/exec?id="&B2))
A3: PC 2 | B3: =CONCATENATE("MPLB-PC-00",RIGHT(A3,LEN(A3) - (FIND(" ",A3))),"-26") -> MPLB-PC-002-26 | C3: KEB1R91 | D3: INTEL CORE i5-3470 | E3: 4.00GB | F3: 119GB V-GEN | G3: WINDOWS 10 | H3: LOGITECH | I3: LOGITECH | J3: VARRO | K3: SIMBADDA | L3: BAIK | M3: ASUSTEK H61M-K | T3: =IMAGE("https://quickchart.io/qr?text="&ENCODEURL("https://script.google.com/macros/s/AKfycbwQpzkxOCRP3NYqoeT2iICUn44Z1fFWd3SGrCOmIeLE-uz8Fxp4eBwg-OJKyc6xQgcnDA/exec?id="&B3))
A4: PC 3 | B4: =CONCATENATE("MPLB-PC-00",RIGHT(A4,LEN(A4) - (FIND(" ",A4))),"-26") -> MPLB-PC-003-26 | C4: ETNE740 | D4: INTEL CORE i5-3470 | E4: 4 GB | F4: 128 GB | G4: WINDOWS | H4: LOGITECH | I4: LOGITECH | J4: VARRO 19 INCH | K4: SIMBADDA | L4: MONITOR MATI | M4: ASUSTEK H61M-K | T4: =IMAGE("https://quickchart.io/qr?text="&ENCODEURL("https://script.google.com/macros/s/AKfycbwQpzkxOCRP3NYqoeT2iICUn44Z1fFWd3SGrCOmIeLE-uz8Fxp4eBwg-OJKyc6xQgcnDA/exec?id="&B4))
A5: PC 4 | B5: =CONCATENATE("MPLB-PC-00",RIGHT(A5,LEN(A5) - (FIND(" ",A5))),"-26") -> MPLB-PC-004-26 | C5: - | D5: INTEL CORE i5-3470 | E5: 4 GB | F5: 128 GB | G5: WINDOWS | H5: LOGITECH | I5: LOGITECH | J5: VARRO | K5: SIMBADDA | L5: GUDANG | M5: ASUSTEK H61M-K | T5: =IMAGE("https://quickchart.io/qr?text="&ENCODEURL("https://script.google.com/macros/s/AKfycbwQpzkxOCRP3NYqoeT2iICUn44Z1fFWd3SGrCOmIeLE-uz8Fxp4eBwg-OJKyc6xQgcnDA/exec?id="&B5))
A6: PC 5 | B6: =CONCATENATE("MPLB-PC-00",RIGHT(A6,LEN(A6) - (FIND(" ",A6))),"-26") -> MPLB-PC-005-26 | C6: DEUSTOR-TOEETF7 | D6: INTEL CORE i5-3470 | E6: 4.00 GB | F6: 119GB V-GEN | G6: WINDOWS 10 | H6: LOGITECH | I6: LOGITECH | J6: VARRO | K6: SIMBADA | L6: BAIK | M6: ASUSTEK H61M-K | T6: =IMAGE("https://quickchart.io/qr?text="&ENCODEURL("https://script.google.com/macros/s/AKfycbwQpzkxOCRP3NYqoeT2iICUn44Z1fFWd3SGrCOmIeLE-uz8Fxp4eBwg-OJKyc6xQgcnDA/exec?id="&B6))
A7: PC 6 | B7: =CONCATENATE("MPLB-PC-00",RIGHT(A7,LEN(A7) - (FIND(" ",A7))),"-26") -> MPLB-PC-006-26 | C7: DEKSTOP-3UVU8 | D7: INTEL CORE i5-3470 | E7: 4.00 GB | F7: 119GB V-GEN | G7: WINDOWS 10 | H7: LOGITECH | I7: LOGITECH | J7: LG | K7: SIMBADDA | L7: BAIK | M7: ASUSTEK H61M-K | T7: =IMAGE("https://quickchart.io/qr?text="&ENCODEURL("https://script.google.com/macros/s/AKfycbwQpzkxOCRP3NYqoeT2iICUn44Z1fFWd3SGrCOmIeLE-uz8Fxp4eBwg-OJKyc6xQgcnDA/exec?id="&B7))
A8: PC 7 | B8: =CONCATENATE("MPLB-PC-00",RIGHT(A8,LEN(A8) - (FIND(" ",A8))),"-26") -> MPLB-PC-007-26 | C8: DEKSTOP-7A5BC8G | D8: INTEL CORE i5-3470 | E8: 4.00 GB | F8: 119GB V-GEN | G8: WINDOWS 10 | H8: LOGITECH | I8: LOGITECH | J8: LG | K8: SIMBADDA | L8: BAIK | M8: ASUSTEK H61M-K | T8: =IMAGE("https://quickchart.io/qr?text="&ENCODEURL("https://script.google.com/macros/s/AKfycbwQpzkxOCRP3NYqoeT2iICUn44Z1fFWd3SGrCOmIeLE-uz8Fxp4eBwg-OJKyc6xQgcnDA/exec?id="&B8))
A9: PC 8 | B9: =CONCATENATE("MPLB-PC-00",RIGHT(A9,LEN(A9) - (FIND(" ",A9))),"-26") -> MPLB-PC-008-26 | C9: - | D9: INTEL CORE i5-3470 | E9: 4 GB | F9: 128 GB | G9: WINDOWS 10 | H9: LOGITECH | I9: LOGITECH | J9: VARRO 19 INCH | K9: SIMBADDA | L9: PSU RUSAK | M9: ASUSTEK H61M-K | T9: =IMAGE("https://quickchart.io/qr?text="&ENCODEURL("https://script.google.com/macros/s/AKfycbwQpzkxOCRP3NYqoeT2iICUn44Z1fFWd3SGrCOmIeLE-uz8Fxp4eBwg-OJKyc6xQgcnDA/exec?id="&B9))
A10: PC 9 | B10: =CONCATENATE("MPLB-PC-00",RIGHT(A10,LEN(A10) - (FIND(" ",A10))),"-26") -> MPLB-PC-009-26 | C10: DEKSTOP-4KSO561 | D10: INTEL CORE i5-3470 | E10: 4.00 GB | F10: 119GB V-GEN | G10: WINDOWS 10 | H10: LOGITECH | I10: LOGITECH | J10: VARRO | K10: SIMBADDA | L10: BAIK | M10: ASUSTEK H61M-K | T10: =IMAGE("https://quickchart.io/qr?text="&ENCODEURL("https://script.google.com/macros/s/AKfycbwQpzkxOCRP3NYqoeT2iICUn44Z1fFWd3SGrCOmIeLE-uz8Fxp4eBwg-OJKyc6xQgcnDA/exec?id="&B10))
A11: PC 10 | B11: =CONCATENATE("MPLB-PC-00",RIGHT(A11,LEN(A11) - (FIND(" ",A11))),"-26") -> MPLB-PC-0010-26 | C11: DESKTOP-H39FJ93 | D11: INTEL CORE i5-3470 | E11: 4.00 GB | F11: 119GB V-GEN | G11: WINDOWS 10 | H11: LOGITECH | I11: LOGITECH | J11: VARRO | K11: SIMBADDA | L11: BAIK | M11: ASUSTEK H61M-K | T11: =IMAGE("https://quickchart.io/qr?text="&ENCODEURL("https://script.google.com/macros/s/AKfycbwQpzkxOCRP3NYqoeT2iICUn44Z1fFWd3SGrCOmIeLE-uz8Fxp4eBwg-OJKyc6xQgcnDA/exec?id="&B11))
A12: PC 11 | B12: =CONCATENATE("MPLB-PC-00",RIGHT(A12,LEN(A12) - (FIND(" ",A12))),"-26") -> MPLB-PC-0011-26 | C12: DEKSTOP-NLH 7QNO | D12: INTEL CORE i5-3470 | E12: 4.00 GB | F12: 119GB V-GEN | G12: WINDOWS 10 | H12: LOGITECH | I12: LOGITECH | J12: LG | K12: SIMBADDA | L12: BAIK | M12: ASUSTEK H61M-K | T12: =IMAGE("https://quickchart.io/qr?text="&ENCODEURL("https://script.google.com/macros/s/AKfycbwQpzkxOCRP3NYqoeT2iICUn44Z1fFWd3SGrCOmIeLE-uz8Fxp4eBwg-OJKyc6xQgcnDA/exec?id="&B12))
A13: PC 12 | B13: =CONCATENATE("MPLB-PC-00",RIGHT(A13,LEN(A13) - (FIND(" ",A13))),"-26") -> MPLB-PC-0012-26 | C13: DESKTOP-N2C3CIH | D13: INTEL CORE i5-3470 | E13: 4.00 GB | F13: 119GB V-GEN | G13: WINDOWS 10 | H13: LOGITECH | I13: LOGITECH | J13: LG | K13: SIMBADDA | L13: BAIK | M13: ASUSTEK H61M-K | T13: =IMAGE("https://quickchart.io/qr?text="&ENCODEURL("https://script.google.com/macros/s/AKfycbwQpzkxOCRP3NYqoeT2iICUn44Z1fFWd3SGrCOmIeLE-uz8Fxp4eBwg-OJKyc6xQgcnDA/exec?id="&B13))
... A15: PC 14 | B15: =CONCATENATE("MPLB-PC-00",RIGHT(A15,LEN(A15) - (FIND(" ",A15))),"-26") -> MPLB-PC-0014-26 | C15: DEKSTOP-T94E7JB | D15: INTEL CORE i5-3470 | E15: 4.00 GB | F15: 119GB V-GEN | G15: WINDOWS 10 | H15: LOGITECH | I15: LOGITECH | J15: LG | K15: SIMBADDA | L15: BAIK | M15: ASUSTEK H61M-K | T15: =IMAGE("https://quickchart.io/qr?text="&ENCODEURL("https://script.google.com/macros/s/AKfycbwQpzkxOCRP3NYqoeT2iICUn44Z1fFWd3SGrCOmIeLE-uz8Fxp4eBwg-OJKyc6xQgcnDA/exec?id="&B15))
A16: PC 15 | B16: =CONCATENATE("MPLB-PC-00",RIGHT(A16,LEN(A16) - (FIND(" ",A16))),"-26") -> MPLB-PC-0015-26 | C16: DEKSTOP-GTGKMGI | D16: INTEL CORE i5-3470 | E16: 4.00 GB | F16: 119GB V-GEN | G16: WINDOWS 10 | H16: LOGITECH | I16: LOGITECH | K16: SIMBADDA | L16: BAIK | M16: ASUSTEK H61M-K | T16: =IMAGE("https://quickchart.io/qr?text="&ENCODEURL("https://script.google.com/macros/s/AKfycbwQpzkxOCRP3NYqoeT2iICUn44Z1fFWd3SGrCOmIeLE-uz8Fxp4eBwg-OJKyc6xQgcnDA/exec?id="&B16))
A17: PC 16 | B17: =CONCATENATE("MPLB-PC-00",RIGHT(A17,LEN(A17) - (FIND(" ",A17))),"-26") -> MPLB-PC-0016-26 | C17: DEKSTOP-2GAAOC2 | D17: INTEL CORE i5-3470 | E17: 4.00 GB | F17: 119GB V-GEN | G17: WINDOWS 10 | H17: LOGITECH | I17: LOGITECH | J17: LG | K17: SIMBADDA | L17: BAIK | M17: ASUSTEK H61M-K | T17: =IMAGE("https://quickchart.io/qr?text="&ENCODEURL("https://script.google.com/macros/s/AKfycbwQpzkxOCRP3NYqoeT2iICUn44Z1fFWd3SGrCOmIeLE-uz8Fxp4eBwg-OJKyc6xQgcnDA/exec?id="&B17))
A18: PC 17 | B18: =CONCATENATE("MPLB-PC-00",RIGHT(A18,LEN(A18) - (FIND(" ",A18))),"-26") -> MPLB-PC-0017-26 | C18: 0173GEK | D18: INTEL CORE i5-3470 | E18: 4.00 GB | F18: 119GB V-GEN | G18: WINDOWS 10 | H18: LOGITECH | I18: LOGITECH | J18: LG | K18: SIMBADDA | L18: BAIK | M18: ASUSTEK H61M-K | T18: =IMAGE("https://quickchart.io/qr?text="&ENCODEURL("https://script.google.com/macros/s/AKfycbwQpzkxOCRP3NYqoeT2iICUn44Z1fFWd3SGrCOmIeLE-uz8Fxp4eBwg-OJKyc6xQgcnDA/exec?id="&B18))
A19: PC 18 | B19: =CONCATENATE("MPLB-PC-00",RIGHT(A19,LEN(A19) - (FIND(" ",A19))),"-26") -> MPLB-PC-0018-26 | C19: P1SUTGN | D19: INTEL CORE i5-3470 | E19: 4.00 GB | F19: 119GB V-GEN | G19: WINDOWS 10 | H19: LOGITECH | I19: LOGITECH | J19: LG | K19: SIMBADDA | L19: BAIK | M19: ASUSTEK H61M-K | T19: =IMAGE("https://quickchart.io/qr?text="&ENCODEURL("https://script.google.com/macros/s/AKfycbwQpzkxOCRP3NYqoeT2iICUn44Z1fFWd3SGrCOmIeLE-uz8Fxp4eBwg-OJKyc6xQgcnDA/exec?id="&B19))
A20: PC 19 | B20: =CONCATENATE("MPLB-PC-00",RIGHT(A20,LEN(A20) - (FIND(" ",A20))),"-26") -> MPLB-PC-0019-26 | C20: 0173GEK | D20: INTEL CORE i5-3470 | E20: 4.00 GB | F20: 119GB V-GEN | G20: WINDOWS 10 | H20: LOGITECH | I20: LOGITECH | J20: LG | K20: SIMBADDA | L20: BAIK | M20: ASUSTEK H61M-K | T20: =IMAGE("https://quickchart.io/qr?text="&ENCODEURL("https://script.google.com/macros/s/AKfycbwQpzkxOCRP3NYqoeT2iICUn44Z1fFWd3SGrCOmIeLE-uz8Fxp4eBwg-OJKyc6xQgcnDA/exec?id="&B20))
A21: PC 20 | B21: =CONCATENATE("MPLB-PC-00",RIGHT(A21,LEN(A21) - (FIND(" ",A21))),"-26") -> MPLB-PC-0020-26 | C21: DEKSTOP-D012N2B | D21: INTEL CORE i5-3470 | E21: 4.00 GB | F21: 119GB V-GEN | G21: WINDOWS 10 | H21: LOGITECH | I21: LOGITECH | J21: LG | K21: SIMBADDA | L21: BAIK | M21: ASUSTEK H61M-K | T21: =IMAGE("https://quickchart.io/qr?text="&ENCODEURL("https://script.google.com/macros/s/AKfycbwQpzkxOCRP3NYqoeT2iICUn44Z1fFWd3SGrCOmIeLE-uz8Fxp4eBwg-OJKyc6xQgcnDA/exec?id="&B21))
A22: PC 21 | B22: =CONCATENATE("MPLB-PC-00",RIGHT(A22,LEN(A22) - (FIND(" ",A22))),"-26") -> MPLB-PC-0021-26 | C22: DEKSTOP-8OE447M | D22: INTEL CORE i5-3470 | E22: 4.00 GB | F22: 119GB V-GEN | G22: WINDOWS 10 | H22: LOGITECH | I22: LOGITECH | J22: LG | K22: SIMBADDA | L22: BAIK | M22: ASUSTEK H61M-K | T22: =IMAGE("https://quickchart.io/qr?text="&ENCODEURL("https://script.google.com/macros/s/AKfycbwQpzkxOCRP3NYqoeT2iICUn44Z1fFWd3SGrCOmIeLE-uz8Fxp4eBwg-OJKyc6xQgcnDA/exec?id="&B22))
A23: PC 22 | B23: =CONCATENATE("MPLB-PC-00",RIGHT(A23,LEN(A23) - (FIND(" ",A23))),"-26") -> MPLB-PC-0022-26 | C23: DOL2N2B | D23: INTEL CORE i5-3470 | E23: 4 GB | F23: 128 GB | G23: WINDOWS 10 | H23: LOGITECH | I23: LOGITECH | J23: LG 19 INCH | K23: SIMBADDA | L23: BAIK | M23: ASUSTEK H61M-K | T23: =IMAGE("https://quickchart.io/qr?text="&ENCODEURL("https://script.google.com/macros/s/AKfycbwQpzkxOCRP3NYqoeT2iICUn44Z1fFWd3SGrCOmIeLE-uz8Fxp4eBwg-OJKyc6xQgcnDA/exec?id="&B23))
A24: PC 23 | B24: =CONCATENATE("MPLB-PC-00",RIGHT(A24,LEN(A24) - (FIND(" ",A24))),"-26") -> MPLB-PC-0023-26 | C24: PMELCUP | D24: INTEL CORE i5-2400 | E24: 8 GB | F24: 500 GB | G24: WINDOWS 10 | H24: LOGITECH | I24: LOGITECH | J24: LG 19 INCH | K24: SIMBADDA | L24: BAIK | M24: GIGABYTE H61M-D52 | T24: =IMAGE("https://quickchart.io/qr?text="&ENCODEURL("https://script.google.com/macros/s/AKfycbwQpzkxOCRP3NYqoeT2iICUn44Z1fFWd3SGrCOmIeLE-uz8Fxp4eBwg-OJKyc6xQgcnDA/exec?id="&B24))
A25: PC 24 | B25: =CONCATENATE("MPLB-PC-00",RIGHT(A25,LEN(A25) - (FIND(" ",A25))),"-26") -> MPLB-PC-0024-26 | C25: UT3VO41 | D25: INTEL CORE i5-2400 | E25: 8.00 GB | F25: 477 GB | G25: WINDOWS 10 | H25: LOGITECH | I25: LOGITECH | J25: LG | K25: SIMBADDA | L25: BAIK | M25: GIGABYTE H61M-D52 | T25: =IMAGE("https://quickchart.io/qr?text="&ENCODEURL("https://script.google.com/macros/s/AKfycbwQpzkxOCRP3NYqoeT2iICUn44Z1fFWd3SGrCOmIeLE-uz8Fxp4eBwg-OJKyc6xQgcnDA/exec?id="&B25))
A26: PC 25 | B26: =CONCATENATE("MPLB-PC-00",RIGHT(A26,LEN(A26) - (FIND(" ",A26))),"-26") -> MPLB-PC-0025-26 | C26: DEKSTOP-QB1CIT7 | D26: INTEL CORE i5-2400 | E26: 8.00 GB | F26: 477 GB | G26: WINDOWS 10 | H26: LOGITECH | I26: LOGITECH | J26: LG | K26: SIMBADDA | L26: BAIK | M26: GIGABYTE H61M-D52 | T26: =IMAGE("https://quickchart.io/qr?text="&ENCODEURL("https://script.google.com/macros/s/AKfycbwQpzkxOCRP3NYqoeT2iICUn44Z1fFWd3SGrCOmIeLE-uz8Fxp4eBwg-OJKyc6xQgcnDA/exec?id="&B26))
A27: PC 26 | B27: =CONCATENATE("MPLB-PC-00",RIGHT(A27,LEN(A27) - (FIND(" ",A27))),"-26") -> MPLB-PC-0026-26 | C27: DEKSTOP-LJ7V6FD | D27: INTEL CORE i5-2400 | E27: 8.00 GB | F27: 477 GB | G27: WINDOWS 10 | H27: LOGITECH | I27: LOGITECH | J27: LG | K27: SIMBADDA | L27: BAIK | M27: GIGABYTE H61M-D52 | T27: =IMAGE("https://quickchart.io/qr?text="&ENCODEURL("https://script.google.com/macros/s/AKfycbwQpzkxOCRP3NYqoeT2iICUn44Z1fFWd3SGrCOmIeLE-uz8Fxp4eBwg-OJKyc6xQgcnDA/exec?id="&B27))
A28: PC 27 | B28: =CONCATENATE("MPLB-PC-00",RIGHT(A28,LEN(A28) - (FIND(" ",A28))),"-26") -> MPLB-PC-0027-26 | C28: DEKSTOP-34ANNBJ | D28: INTEL CORE i5-2400 | E28: 8.00 GB | F28: 477 GB | G28: WINDOWS 10 | H28: LOGITECH | I28: LOGITECH | J28: LG | K28: SIMBADDA | L28: BAIK | M28: GIGABYTE H61M-D52 | T28: =IMAGE("https://quickchart.io/qr?text="&ENCODEURL("https://script.google.com/macros/s/AKfycbwQpzkxOCRP3NYqoeT2iICUn44Z1fFWd3SGrCOmIeLE-uz8Fxp4eBwg-OJKyc6xQgcnDA/exec?id="&B28))
... A37: PC 36 | B37: =CONCATENATE("MPLB-PC-00",RIGHT(A37,LEN(A37) - (FIND(" ",A37))),"-26") -> MPLB-PC-0036-26 | C37: CGUV320 | D37: INTEL CORE i5-3470 | E37: 4 GB | F37: 128 GB | G37: WINDOWS 10 | H37: LOGITECH | I37: LOGITECH | J37: VARRO 19 INCH | K37: SIMBADDA | L37: MONITOR MATI | M37: ASUS P9H61-MX R2.0 | T37: =IMAGE("https://quickchart.io/qr?text="&ENCODEURL("https://script.google.com/macros/s/AKfycbwQpzkxOCRP3NYqoeT2iICUn44Z1fFWd3SGrCOmIeLE-uz8Fxp4eBwg-OJKyc6xQgcnDA/exec?id="&B37))

Sheet BARCODE MPLB
A1: {=IFERROR(INDEX(MPLB!$T:$T, (ROUNDUP(ROW()/2,0)-1)*5 + COLUMN() + 1), "")} | B1: {=IFERROR(INDEX(MPLB!$T:$T, (ROUNDUP(ROW()/2,0)-1)*5 + COLUMN() + 1), "")} | C1: {=IFERROR(INDEX(MPLB!$T:$T, (ROUNDUP(ROW()/2,0)-1)*5 + COLUMN() + 1), "")} | D1: {=IFERROR(INDEX(MPLB!$T:$T, (ROUNDUP(ROW()/2,0)-1)*5 + COLUMN() + 1), "")} | E1: {=IFERROR(INDEX(MPLB!$T:$T, (ROUNDUP(ROW()/2,0)-1)*5 + COLUMN() + 1), "")}
A2: {=IFERROR(INDEX(MPLB!$B:$B, (ROW()/2-1)*5 + COLUMN() + 1), "")} -> MPLB-PC-001-26 | B2: {=IFERROR(INDEX(MPLB!$B:$B, (ROW()/2-1)*5 + COLUMN() + 1), "")} -> MPLB-PC-002-26 | C2: {=IFERROR(INDEX(MPLB!$B:$B, (ROW()/2-1)*5 + COLUMN() + 1), "")} -> MPLB-PC-003-26 | D2: {=IFERROR(INDEX(MPLB!$B:$B, (ROW()/2-1)*5 + COLUMN() + 1), "")} -> MPLB-PC-004-26 | E2: {=IFERROR(INDEX(MPLB!$B:$B, (ROW()/2-1)*5 + COLUMN() + 1), "")} -> MPLB-PC-005-26
A3: {=IFERROR(INDEX(MPLB!$T:$T, (ROUNDUP(ROW()/2,0)-1)*5 + COLUMN() + 1), "")} | B3: {=IFERROR(INDEX(MPLB!$T:$T, (ROUNDUP(ROW()/2,0)-1)*5 + COLUMN() + 1), "")} | C3: {=IFERROR(INDEX(MPLB!$T:$T, (ROUNDUP(ROW()/2,0)-1)*5 + COLUMN() + 1), "")} | D3: {=IFERROR(INDEX(MPLB!$T:$T, (ROUNDUP(ROW()/2,0)-1)*5 + COLUMN() + 1), "")} | E3: {=IFERROR(INDEX(MPLB!$T:$T, (ROUNDUP(ROW()/2,0)-1)*5 + COLUMN() + 1), "")}
A4: {=IFERROR(INDEX(MPLB!$B:$B, (ROW()/2-1)*5 + COLUMN() + 1), "")} -> MPLB-PC-006-26 | B4: {=IFERROR(INDEX(MPLB!$B:$B, (ROW()/2-1)*5 + COLUMN() + 1), "")} -> MPLB-PC-007-26 | C4: {=IFERROR(INDEX(MPLB!$B:$B, (ROW()/2-1)*5 + COLUMN() + 1), "")} -> MPLB-PC-008-26 | D4: {=IFERROR(INDEX(MPLB!$B:$B, (ROW()/2-1)*5 + COLUMN() + 1), "")} -> MPLB-PC-009-26 | E4: {=IFERROR(INDEX(MPLB!$B:$B, (ROW()/2-1)*5 + COLUMN() + 1), "")} -> MPLB-PC-0010-26
A5: {=IFERROR(INDEX(MPLB!$T:$T, (ROUNDUP(ROW()/2,0)-1)*5 + COLUMN() + 1), "")} | B5: {=IFERROR(INDEX(MPLB!$T:$T, (ROUNDUP(ROW()/2,0)-1)*5 + COLUMN() + 1), "")} | C5: {=IFERROR(INDEX(MPLB!$T:$T, (ROUNDUP(ROW()/2,0)-1)*5 + COLUMN() + 1), "")} | D5: {=IFERROR(INDEX(MPLB!$T:$T, (ROUNDUP(ROW()/2,0)-1)*5 + COLUMN() + 1), "")} | E5: {=IFERROR(INDEX(MPLB!$T:$T, (ROUNDUP(ROW()/2,0)-1)*5 + COLUMN() + 1), "")}
A6: {=IFERROR(INDEX(MPLB!$B:$B, (ROW()/2-1)*5 + COLUMN() + 1), "")} -> MPLB-PC-0011-26 | B6: {=IFERROR(INDEX(MPLB!$B:$B, (ROW()/2-1)*5 + COLUMN() + 1), "")} -> MPLB-PC-0012-26 | C6: {=IFERROR(INDEX(MPLB!$B:$B, (ROW()/2-1)*5 + COLUMN() + 1), "")} -> MPLB-PC-0013-26 | D6: {=IFERROR(INDEX(MPLB!$B:$B, (ROW()/2-1)*5 + COLUMN() + 1), "")} -> MPLB-PC-0014-26 | E6: {=IFERROR(INDEX(MPLB!$B:$B, (ROW()/2-1)*5 + COLUMN() + 1), "")} -> MPLB-PC-0015-26
A7: {=IFERROR(INDEX(MPLB!$T:$T, (ROUNDUP(ROW()/2,0)-1)*5 + COLUMN() + 1), "")} | B7: {=IFERROR(INDEX(MPLB!$T:$T, (ROUNDUP(ROW()/2,0)-1)*5 + COLUMN() + 1), "")} | C7: {=IFERROR(INDEX(MPLB!$T:$T, (ROUNDUP(ROW()/2,0)-1)*5 + COLUMN() + 1), "")} | D7: {=IFERROR(INDEX(MPLB!$T:$T, (ROUNDUP(ROW()/2,0)-1)*5 + COLUMN() + 1), "")} | E7: {=IFERROR(INDEX(MPLB!$T:$T, (ROUNDUP(ROW()/2,0)-1)*5 + COLUMN() + 1), "")}
A8: {=IFERROR(INDEX(MPLB!$B:$B, (ROW()/2-1)*5 + COLUMN() + 1), "")} -> MPLB-PC-0016-26 | B8: {=IFERROR(INDEX(MPLB!$B:$B, (ROW()/2-1)*5 + COLUMN() + 1), "")} -> MPLB-PC-0017-26 | C8: {=IFERROR(INDEX(MPLB!$B:$B, (ROW()/2-1)*5 + COLUMN() + 1), "")} -> MPLB-PC-0018-26 | D8: {=IFERROR(INDEX(MPLB!$B:$B, (ROW()/2-1)*5 + COLUMN() + 1), "")} -> MPLB-PC-0019-26 | E8: {=IFERROR(INDEX(MPLB!$B:$B, (ROW()/2-1)*5 + COLUMN() + 1), "")} -> MPLB-PC-0020-26
A9: {=IFERROR(INDEX(MPLB!$T:$T, (ROUNDUP(ROW()/2,0)-1)*5 + COLUMN() + 1), "")} | B9: {=IFERROR(INDEX(MPLB!$T:$T, (ROUNDUP(ROW()/2,0)-1)*5 + COLUMN() + 1), "")} | C9: {=IFERROR(INDEX(MPLB!$T:$T, (ROUNDUP(ROW()/2,0)-1)*5 + COLUMN() + 1), "")} | D9: {=IFERROR(INDEX(MPLB!$T:$T, (ROUNDUP(ROW()/2,0)-1)*5 + COLUMN() + 1), "")} | E9: {=IFERROR(INDEX(MPLB!$T:$T, (ROUNDUP(ROW()/2,0)-1)*5 + COLUMN() + 1), "")}
A10: {=IFERROR(INDEX(MPLB!$B:$B, (ROW()/2-1)*5 + COLUMN() + 1), "")} -> MPLB-PC-0021-26 | B10: {=IFERROR(INDEX(MPLB!$B:$B, (ROW()/2-1)*5 + COLUMN() + 1), "")} -> MPLB-PC-0022-26 | C10: {=IFERROR(INDEX(MPLB!$B:$B, (ROW()/2-1)*5 + COLUMN() + 1), "")} -> MPLB-PC-0023-26 | D10: {=IFERROR(INDEX(MPLB!$B:$B, (ROW()/2-1)*5 + COLUMN() + 1), "")} -> MPLB-PC-0024-26 | E10: {=IFERROR(INDEX(MPLB!$B:$B, (ROW()/2-1)*5 + COLUMN() + 1), "")} -> MPLB-PC-0025-26
A11: {=IFERROR(INDEX(MPLB!$T:$T, (ROUNDUP(ROW()/2,0)-1)*5 + COLUMN() + 1), "")} | B11: {=IFERROR(INDEX(MPLB!$T:$T, (ROUNDUP(ROW()/2,0)-1)*5 + COLUMN() + 1), "")} | C11: {=IFERROR(INDEX(MPLB!$T:$T, (ROUNDUP(ROW()/2,0)-1)*5 + COLUMN() + 1), "")} | D11: {=IFERROR(INDEX(MPLB!$T:$T, (ROUNDUP(ROW()/2,0)-1)*5 + COLUMN() + 1), "")} | E11: {=IFERROR(INDEX(MPLB!$T:$T, (ROUNDUP(ROW()/2,0)-1)*5 + COLUMN() + 1), "")}
A12: {=IFERROR(INDEX(MPLB!$B:$B, (ROW()/2-1)*5 + COLUMN() + 1), "")} -> MPLB-PC-0026-26 | B12: {=IFERROR(INDEX(MPLB!$B:$B, (ROW()/2-1)*5 + COLUMN() + 1), "")} -> MPLB-PC-0027-26 | C12: {=IFERROR(INDEX(MPLB!$B:$B, (ROW()/2-1)*5 + COLUMN() + 1), "")} -> MPLB-PC-0028-26 | D12: {=IFERROR(INDEX(MPLB!$B:$B, (ROW()/2-1)*5 + COLUMN() + 1), "")} -> MPLB-PC-0029-26 | E12: {=IFERROR(INDEX(MPLB!$B:$B, (ROW()/2-1)*5 + COLUMN() + 1), "")} -> MPLB-PC-0030-26
A13: {=IFERROR(INDEX(MPLB!$T:$T, (ROUNDUP(ROW()/2,0)-1)*5 + COLUMN() + 1), "")} | B13: {=IFERROR(INDEX(MPLB!$T:$T, (ROUNDUP(ROW()/2,0)-1)*5 + COLUMN() + 1), "")} | C13: {=IFERROR(INDEX(MPLB!$T:$T, (ROUNDUP(ROW()/2,0)-1)*5 + COLUMN() + 1), "")} | D13: {=IFERROR(INDEX(MPLB!$T:$T, (ROUNDUP(ROW()/2,0)-1)*5 + COLUMN() + 1), "")} | E13: {=IFERROR(INDEX(MPLB!$T:$T, (ROUNDUP(ROW()/2,0)-1)*5 + COLUMN() + 1), "")}
A14: {=IFERROR(INDEX(MPLB!$B:$B, (ROW()/2-1)*5 + COLUMN() + 1), "")} -> MPLB-PC-0031-26 | B14: {=IFERROR(INDEX(MPLB!$B:$B, (ROW()/2-1)*5 + COLUMN() + 1), "")} -> MPLB-PC-0032-26 | C14: {=IFERROR(INDEX(MPLB!$B:$B, (ROW()/2-1)*5 + COLUMN() + 1), "")} -> MPLB-PC-0033-26 | D14: {=IFERROR(INDEX(MPLB!$B:$B, (ROW()/2-1)*5 + COLUMN() + 1), "")} -> MPLB-PC-0034-26 | E14: {=IFERROR(INDEX(MPLB!$B:$B, (ROW()/2-1)*5 + COLUMN() + 1), "")} -> MPLB-PC-0035-26
A15: {=IFERROR(INDEX(MPLB!$T:$T, (ROUNDUP(ROW()/2,0)-1)*5 + COLUMN() + 1), "")} | B15: {=IFERROR(INDEX(MPLB!$T:$T, (ROUNDUP(ROW()/2,0)-1)*5 + COLUMN() + 1), "")} | C15: {=IFERROR(INDEX(MPLB!$T:$T, (ROUNDUP(ROW()/2,0)-1)*5 + COLUMN() + 1), "")} | D15: {=IFERROR(INDEX(MPLB!$T:$T, (ROUNDUP(ROW()/2,0)-1)*5 + COLUMN() + 1), "")} | E15: {=IFERROR(INDEX(MPLB!$T:$T, (ROUNDUP(ROW()/2,0)-1)*5 + COLUMN() + 1), "")}
A16: {=IFERROR(INDEX(MPLB!$B:$B, (ROW()/2-1)*5 + COLUMN() + 1), "")} -> MPLB-PC-0036-26 | B16: {=IFERROR(INDEX(MPLB!$B:$B, (ROW()/2-1)*5 + COLUMN() + 1), "")} | C16: {=IFERROR(INDEX(MPLB!$B:$B, (ROW()/2-1)*5 + COLUMN() + 1), "")} | D16: {=IFERROR(INDEX(MPLB!$B:$B, (ROW()/2-1)*5 + COLUMN() + 1), "")} | E16: {=IFERROR(INDEX(MPLB!$B:$B, (ROW()/2-1)*5 + COLUMN() + 1), "")}

Sheet DKV
A1: NO | B1: KODE ASET | C1: NAMA PC | D1: PROSESOR | E1: RAM | F1: STORAGE | G1: OS | H1: KEYBOARD | I1: MOUSE | J1: MONITOR | K1: MEREK CASING | L1: KONDISI | M1: Motherboard | N1: LOKASI | O1: TAHUN PENGADAAN | P1: TANGGAL PENDATAAN | Q1: PETUGAS PENDATA | R1: FOTO | S1: CATATAN | T1: BARCODE
A2: PC 1 | B2: =CONCATENATE("DKV-PC-00",RIGHT(A2,LEN(A2) - (FIND(" ",A2))),"-26") -> DKV-PC-001-26 | C2: DEKSTOP-8DOENKN | D2: INTEL CORE i7-6700 | E2: 16 GB | F2: 237 GB | G2: WINDOWS 11 | H2: LOGITECH | I2: LOGITECH | J2: LG 24 INC | K2: VARRO MACQUA | L2: BAIK | M2: INTEL H110 | T2: =IMAGE("https://quickchart.io/qr?text="&ENCODEURL("https://script.google.com/macros/s/AKfycbwQpzkxOCRP3NYqoeT2iICUn44Z1fFWd3SGrCOmIeLE-uz8Fxp4eBwg-OJKyc6xQgcnDA/exec?id="&B2))
A3: PC 2 | B3: =CONCATENATE("DKV-PC-00",RIGHT(A3,LEN(A3) - (FIND(" ",A3))),"-26") -> DKV-PC-002-26 | C3: DEKSTOP-10J8GOF | D3: INTEL CORE i7-6700 | E3: 16 GB | F3: 237 GB | G3: WINDOWS 11 | H3: LOGITECH | I3: LOGITECH | J3: LG 24 INC | K3: VARRO MACQUA | L3: BAIK | M3: INTEL H110 | T3: =IMAGE("https://quickchart.io/qr?text="&ENCODEURL("https://script.google.com/macros/s/AKfycbwQpzkxOCRP3NYqoeT2iICUn44Z1fFWd3SGrCOmIeLE-uz8Fxp4eBwg-OJKyc6xQgcnDA/exec?id="&B3))
A4: PC 3 | B4: =CONCATENATE("DKV-PC-00",RIGHT(A4,LEN(A4) - (FIND(" ",A4))),"-26") -> DKV-PC-003-26 | C4: DEKSTOP-67AP5HB | D4: INTEL CORE i7-6700 | E4: 16 GB | F4: 237 GB | G4: WINDOWS 11 | H4: LOGITECH | I4: LOGITECH | J4: LG 24 INC | K4: VARRO MACQUA | L4: BAIK | M4: INTEL H110 | T4: =IMAGE("https://quickchart.io/qr?text="&ENCODEURL("https://script.google.com/macros/s/AKfycbwQpzkxOCRP3NYqoeT2iICUn44Z1fFWd3SGrCOmIeLE-uz8Fxp4eBwg-OJKyc6xQgcnDA/exec?id="&B4))
A5: PC 4 | B5: =CONCATENATE("DKV-PC-00",RIGHT(A5,LEN(A5) - (FIND(" ",A5))),"-26") -> DKV-PC-004-26 | C5: DEKSTOP-7PJM40N | D5: INTEL CORE i7-6700 | E5: 16 GB | F5: 237 GB | G5: WINDOWS 11 | H5: LOGITECH | I5: LOGITECH | J5: LG 24 INC | K5: VARRO MACQUA | L5: BAIK | M5: INTEL H110 | T5: =IMAGE("https://quickchart.io/qr?text="&ENCODEURL("https://script.google.com/macros/s/AKfycbwQpzkxOCRP3NYqoeT2iICUn44Z1fFWd3SGrCOmIeLE-uz8Fxp4eBwg-OJKyc6xQgcnDA/exec?id="&B5))
A6: PC 5 | B6: =CONCATENATE("DKV-PC-00",RIGHT(A6,LEN(A6) - (FIND(" ",A6))),"-26") -> DKV-PC-005-26 | C6: DEKSTOP-5GN44A10 | D6: INTEL CORE i7-6700 | E6: 16 GB | F6: 237 GB | G6: WINDOWS 11 | H6: LOGITECH | I6: LOGITECH | J6: LG 24 INC | K6: VARRO MACQUA | L6: BAIK | M6: INTEL H110 | T6: =IMAGE("https://quickchart.io/qr?text="&ENCODEURL("https://script.google.com/macros/s/AKfycbwQpzkxOCRP3NYqoeT2iICUn44Z1fFWd3SGrCOmIeLE-uz8Fxp4eBwg-OJKyc6xQgcnDA/exec?id="&B6))
A7: PC 6 | B7: =CONCATENATE("DKV-PC-00",RIGHT(A7,LEN(A7) - (FIND(" ",A7))),"-26") -> DKV-PC-006-26 | C7: DEKSTOP-C5MK8QD | D7: INTEL CORE i7-6700 | E7: 16 GB | F7: 237 GB | G7: WINDOWS 11 | H7: LOGITECH | I7: LOGITECH | J7: LG 24 INC | K7: VARRO MACQUA | L7: BAIK | M7: INTEL H110 | T7: =IMAGE("https://quickchart.io/qr?text="&ENCODEURL("https://script.google.com/macros/s/AKfycbwQpzkxOCRP3NYqoeT2iICUn44Z1fFWd3SGrCOmIeLE-uz8Fxp4eBwg-OJKyc6xQgcnDA/exec?id="&B7))
A8: PC 7 | B8: =CONCATENATE("DKV-PC-00",RIGHT(A8,LEN(A8) - (FIND(" ",A8))),"-26") -> DKV-PC-007-26 | C8: DEKSTOP-EC91478 | D8: INTEL CORE i7-6700 | E8: 16 GB | F8: 237 GB | G8: WINDOWS 11 | H8: LOGITECH | I8: LOGITECH | J8: LG 24 INC | K8: VARRO MACQUA | L8: BAIK | M8: INTEL H110 | T8: =IMAGE("https://quickchart.io/qr?text="&ENCODEURL("https://script.google.com/macros/s/AKfycbwQpzkxOCRP3NYqoeT2iICUn44Z1fFWd3SGrCOmIeLE-uz8Fxp4eBwg-OJKyc6xQgcnDA/exec?id="&B8))
A9: PC 8 | B9: =CONCATENATE("DKV-PC-00",RIGHT(A9,LEN(A9) - (FIND(" ",A9))),"-26") -> DKV-PC-008-26 | C9: DEKSTOP-K085CBF | D9: INTEL CORE i7-6700 | E9: 16 GB | F9: 237 GB | G9: WINDOWS 11 | H9: LOGITECH | I9: LOGITECH | J9: LG 24 INC | K9: VARRO MACQUA | L9: BAIK | M9: INTEL H110 | T9: =IMAGE("https://quickchart.io/qr?text="&ENCODEURL("https://script.google.com/macros/s/AKfycbwQpzkxOCRP3NYqoeT2iICUn44Z1fFWd3SGrCOmIeLE-uz8Fxp4eBwg-OJKyc6xQgcnDA/exec?id="&B9))
A10: PC 9 | B10: =CONCATENATE("DKV-PC-00",RIGHT(A10,LEN(A10) - (FIND(" ",A10))),"-26") -> DKV-PC-009-26 | C10: DEKSTOP-73M9314 | D10: INTEL CORE i7-6700 | E10: 16 GB | F10: 237 GB | G10: WINDOWS 11 | H10: LOGITECH | I10: LOGITECH | J10: LG 24 INC | K10: VARRO MACQUA | L10: BAIK | M10: INTEL H110 | T10: =IMAGE("https://quickchart.io/qr?text="&ENCODEURL("https://script.google.com/macros/s/AKfycbwQpzkxOCRP3NYqoeT2iICUn44Z1fFWd3SGrCOmIeLE-uz8Fxp4eBwg-OJKyc6xQgcnDA/exec?id="&B10))
A11: PC 10 | B11: =CONCATENATE("DKV-PC-00",RIGHT(A11,LEN(A11) - (FIND(" ",A11))),"-26") -> DKV-PC-0010-26 | C11: DEKSTOP-FBLQJDD | D11: INTEL CORE i7-6700 | E11: 16 GB | F11: 237 GB | G11: WINDOWS 11 | H11: LOGITECH | I11: LOGITECH | J11: LG 24 INC | K11: VARRO MACQUA | L11: BAIK | M11: INTEL H110 | T11: =IMAGE("https://quickchart.io/qr?text="&ENCODEURL("https://script.google.com/macros/s/AKfycbwQpzkxOCRP3NYqoeT2iICUn44Z1fFWd3SGrCOmIeLE-uz8Fxp4eBwg-OJKyc6xQgcnDA/exec?id="&B11))
A12: PC 11 | B12: =CONCATENATE("DKV-PC-00",RIGHT(A12,LEN(A12) - (FIND(" ",A12))),"-26") -> DKV-PC-0011-26 | C12: DEKSTOP-POGE9UI | D12: INTEL CORE i7-6700 | E12: 16 GB | F12: 237 GB | G12: WINDOWS 11 | H12: LOGITECH | I12: LOGITECH | J12: LG 24 INC | K12: VARRO MACQUA | L12: BAIK | M12: INTEL H110 | T12: =IMAGE("https://quickchart.io/qr?text="&ENCODEURL("https://script.google.com/macros/s/AKfycbwQpzkxOCRP3NYqoeT2iICUn44Z1fFWd3SGrCOmIeLE-uz8Fxp4eBwg-OJKyc6xQgcnDA/exec?id="&B12))
A13: PC 12 | B13: =CONCATENATE("DKV-PC-00",RIGHT(A13,LEN(A13) - (FIND(" ",A13))),"-26") -> DKV-PC-0012-26 | C13: DEKSTOP-IMINSRH | D13: INTEL CORE i7-6700 | E13: 16 GB | F13: 237 GB | G13: WINDOWS 11 | H13: LOGITECH | I13: LOGITECH | J13: LG 24 INC | K13: VARRO MACQUA | L13: BAIK | M13: INTEL H110 | T13: =IMAGE("https://quickchart.io/qr?text="&ENCODEURL("https://script.google.com/macros/s/AKfycbwQpzkxOCRP3NYqoeT2iICUn44Z1fFWd3SGrCOmIeLE-uz8Fxp4eBwg-OJKyc6xQgcnDA/exec?id="&B13))
... A29: PC 28 | B29: =CONCATENATE("DKV-PC-00",RIGHT(A29,LEN(A29) - (FIND(" ",A29))),"-26") -> DKV-PC-0028-26 | C29: RB2KDR4 | D29: INTEL CORE i5-3470 | E29: 8 GB | F29: 500 GB | G29: WINDOWS 10 | H29: LOGITECH | I29: LOGITECH | J29: SAMSUNG 19 INCH | K29: AVARIS | L29: BAIK | M29: INTEL H61 | T29: =IMAGE("https://quickchart.io/qr?text="&ENCODEURL("https://script.google.com/macros/s/AKfycbwQpzkxOCRP3NYqoeT2iICUn44Z1fFWd3SGrCOmIeLE-uz8Fxp4eBwg-OJKyc6xQgcnDA/exec?id="&B29))
C32: Notes:
C33: Ada 11 PC rusak bekas DKV (baru ini)
C35: Total: 22 PC di Gudang

Sheet BARCODE DKV
A1: {=IFERROR(INDEX(DKV!$T:$T, (ROUNDUP(ROW()/2,0)-1)*5 + COLUMN() + 1), "")} | B1: {=IFERROR(INDEX(DKV!$T:$T, (ROUNDUP(ROW()/2,0)-1)*5 + COLUMN() + 1), "")} | C1: {=IFERROR(INDEX(DKV!$T:$T, (ROUNDUP(ROW()/2,0)-1)*5 + COLUMN() + 1), "")} | D1: {=IFERROR(INDEX(DKV!$T:$T, (ROUNDUP(ROW()/2,0)-1)*5 + COLUMN() + 1), "")} | E1: {=IFERROR(INDEX(DKV!$T:$T, (ROUNDUP(ROW()/2,0)-1)*5 + COLUMN() + 1), "")}
A2: {=IFERROR(INDEX(DKV!$B:$B, (ROW()/2-1)*5 + COLUMN() + 1), "")} -> DKV-PC-001-26 | B2: {=IFERROR(INDEX(DKV!$B:$B, (ROW()/2-1)*5 + COLUMN() + 1), "")} -> DKV-PC-002-26 | C2: {=IFERROR(INDEX(DKV!$B:$B, (ROW()/2-1)*5 + COLUMN() + 1), "")} -> DKV-PC-003-26 | D2: {=IFERROR(INDEX(DKV!$B:$B, (ROW()/2-1)*5 + COLUMN() + 1), "")} -> DKV-PC-004-26 | E2: {=IFERROR(INDEX(DKV!$B:$B, (ROW()/2-1)*5 + COLUMN() + 1), "")} -> DKV-PC-005-26
A3: {=IFERROR(INDEX(DKV!$T:$T, (ROUNDUP(ROW()/2,0)-1)*5 + COLUMN() + 1), "")} | B3: {=IFERROR(INDEX(DKV!$T:$T, (ROUNDUP(ROW()/2,0)-1)*5 + COLUMN() + 1), "")} | C3: {=IFERROR(INDEX(DKV!$T:$T, (ROUNDUP(ROW()/2,0)-1)*5 + COLUMN() + 1), "")} | D3: {=IFERROR(INDEX(DKV!$T:$T, (ROUNDUP(ROW()/2,0)-1)*5 + COLUMN() + 1), "")} | E3: {=IFERROR(INDEX(DKV!$T:$T, (ROUNDUP(ROW()/2,0)-1)*5 + COLUMN() + 1), "")}
A4: {=IFERROR(INDEX(DKV!$B:$B, (ROW()/2-1)*5 + COLUMN() + 1), "")} -> DKV-PC-006-26 | B4: {=IFERROR(INDEX(DKV!$B:$B, (ROW()/2-1)*5 + COLUMN() + 1), "")} -> DKV-PC-007-26 | C4: {=IFERROR(INDEX(DKV!$B:$B, (ROW()/2-1)*5 + COLUMN() + 1), "")} -> DKV-PC-008-26 | D4: {=IFERROR(INDEX(DKV!$B:$B, (ROW()/2-1)*5 + COLUMN() + 1), "")} -> DKV-PC-009-26 | E4: {=IFERROR(INDEX(DKV!$B:$B, (ROW()/2-1)*5 + COLUMN() + 1), "")} -> DKV-PC-0010-26
A5: {=IFERROR(INDEX(DKV!$T:$T, (ROUNDUP(ROW()/2,0)-1)*5 + COLUMN() + 1), "")} | B5: {=IFERROR(INDEX(DKV!$T:$T, (ROUNDUP(ROW()/2,0)-1)*5 + COLUMN() + 1), "")} | C5: {=IFERROR(INDEX(DKV!$T:$T, (ROUNDUP(ROW()/2,0)-1)*5 + COLUMN() + 1), "")} | D5: {=IFERROR(INDEX(DKV!$T:$T, (ROUNDUP(ROW()/2,0)-1)*5 + COLUMN() + 1), "")} | E5: {=IFERROR(INDEX(DKV!$T:$T, (ROUNDUP(ROW()/2,0)-1)*5 + COLUMN() + 1), "")}
A6: {=IFERROR(INDEX(DKV!$B:$B, (ROW()/2-1)*5 + COLUMN() + 1), "")} -> DKV-PC-0011-26 | B6: {=IFERROR(INDEX(DKV!$B:$B, (ROW()/2-1)*5 + COLUMN() + 1), "")} -> DKV-PC-0012-26 | C6: {=IFERROR(INDEX(DKV!$B:$B, (ROW()/2-1)*5 + COLUMN() + 1), "")} -> DKV-PC-0013-26 | D6: {=IFERROR(INDEX(DKV!$B:$B, (ROW()/2-1)*5 + COLUMN() + 1), "")} -> DKV-PC-0014-26 | E6: {=IFERROR(INDEX(DKV!$B:$B, (ROW()/2-1)*5 + COLUMN() + 1), "")} -> DKV-PC-0015-26
A7: {=IFERROR(INDEX(DKV!$T:$T, (ROUNDUP(ROW()/2,0)-1)*5 + COLUMN() + 1), "")} | B7: {=IFERROR(INDEX(DKV!$T:$T, (ROUNDUP(ROW()/2,0)-1)*5 + COLUMN() + 1), "")} | C7: {=IFERROR(INDEX(DKV!$T:$T, (ROUNDUP(ROW()/2,0)-1)*5 + COLUMN() + 1), "")} | D7: {=IFERROR(INDEX(DKV!$T:$T, (ROUNDUP(ROW()/2,0)-1)*5 + COLUMN() + 1), "")} | E7: {=IFERROR(INDEX(DKV!$T:$T, (ROUNDUP(ROW()/2,0)-1)*5 + COLUMN() + 1), "")}
A8: {=IFERROR(INDEX(DKV!$B:$B, (ROW()/2-1)*5 + COLUMN() + 1), "")} -> DKV-PC-0016-26 | B8: {=IFERROR(INDEX(DKV!$B:$B, (ROW()/2-1)*5 + COLUMN() + 1), "")} -> DKV-PC-0017-26 | C8: {=IFERROR(INDEX(DKV!$B:$B, (ROW()/2-1)*5 + COLUMN() + 1), "")} -> DKV-PC-0018-26 | D8: {=IFERROR(INDEX(DKV!$B:$B, (ROW()/2-1)*5 + COLUMN() + 1), "")} -> DKV-PC-0019-26 | E8: {=IFERROR(INDEX(DKV!$B:$B, (ROW()/2-1)*5 + COLUMN() + 1), "")} -> DKV-PC-0020-26
A9: {=IFERROR(INDEX(DKV!$T:$T, (ROUNDUP(ROW()/2,0)-1)*5 + COLUMN() + 1), "")} | B9: {=IFERROR(INDEX(DKV!$T:$T, (ROUNDUP(ROW()/2,0)-1)*5 + COLUMN() + 1), "")} | C9: {=IFERROR(INDEX(DKV!$T:$T, (ROUNDUP(ROW()/2,0)-1)*5 + COLUMN() + 1), "")} | D9: {=IFERROR(INDEX(DKV!$T:$T, (ROUNDUP(ROW()/2,0)-1)*5 + COLUMN() + 1), "")} | E9: {=IFERROR(INDEX(DKV!$T:$T, (ROUNDUP(ROW()/2,0)-1)*5 + COLUMN() + 1), "")}
A10: {=IFERROR(INDEX(DKV!$B:$B, (ROW()/2-1)*5 + COLUMN() + 1), "")} -> DKV-PC-0021-26 | B10: {=IFERROR(INDEX(DKV!$B:$B, (ROW()/2-1)*5 + COLUMN() + 1), "")} -> DKV-PC-0022-26 | C10: {=IFERROR(INDEX(DKV!$B:$B, (ROW()/2-1)*5 + COLUMN() + 1), "")} -> DKV-PC-0023-26 | D10: {=IFERROR(INDEX(DKV!$B:$B, (ROW()/2-1)*5 + COLUMN() + 1), "")} -> DKV-PC-0024-26 | E10: {=IFERROR(INDEX(DKV!$B:$B, (ROW()/2-1)*5 + COLUMN() + 1), "")} -> DKV-PC-0025-26
A11: {=IFERROR(INDEX(DKV!$T:$T, (ROUNDUP(ROW()/2,0)-1)*5 + COLUMN() + 1), "")} | B11: {=IFERROR(INDEX(DKV!$T:$T, (ROUNDUP(ROW()/2,0)-1)*5 + COLUMN() + 1), "")} | C11: {=IFERROR(INDEX(DKV!$T:$T, (ROUNDUP(ROW()/2,0)-1)*5 + COLUMN() + 1), "")}
A12: {=IFERROR(INDEX(DKV!$B:$B, (ROW()/2-1)*5 + COLUMN() + 1), "")} -> DKV-PC-0026-26 | B12: {=IFERROR(INDEX(DKV!$B:$B, (ROW()/2-1)*5 + COLUMN() + 1), "")} -> DKV-PC-0027-26 | C12: {=IFERROR(INDEX(DKV!$B:$B, (ROW()/2-1)*5 + COLUMN() + 1), "")} -> DKV-PC-0028-26

Sheet AKL
A1: NO | B1: KODE ASET | C1: NAMA PC | D1: PROSESOR | E1: RAM | F1: STORAGE | G1: OS | H1: KEYBOARD | I1: MOUSE | J1: MONITOR | K1: MEREK CASING | L1: KONDISI | M1: Motherboard | N1: LOKASI | O1: TAHUN PENGADAAN | P1: TANGGAL PENDATAAN | Q1: PETUGAS PENDATA | R1: FOTO | S1: CATATAN | T1: BARCODE
A2: PC 1 | B2: =CONCATENATE("AKL-PC-00",RIGHT(A2,LEN(A2) - (FIND(" ",A2))),"-26") -> AKL-PC-001-26 | C2: - | D2: - | E2: - | F2: - | G2: - | H2: LOGITECH | I2: LOGITECH | J2: LG 19 INC | K2: - | L2: GUDANG | M2: - | T2: =IMAGE("https://quickchart.io/qr?text="&ENCODEURL("https://script.google.com/macros/s/AKfycbwQpzkxOCRP3NYqoeT2iICUn44Z1fFWd3SGrCOmIeLE-uz8Fxp4eBwg-OJKyc6xQgcnDA/exec?id="&B2))
A3: PC 2 | B3: =CONCATENATE("AKL-PC-00",RIGHT(A3,LEN(A3) - (FIND(" ",A3))),"-26") -> AKL-PC-002-26 | C3: LLDHHQS | D3: i3-2120 | E3: 4 GB | F3: 128 GB | G3: WINDOWS 10 | H3: LOGITECH | I3: LOGITECH | J3: LG 14 INC | K3: AVARIS | L3: BAIK | M3: INTEL H61 | T3: =IMAGE("https://quickchart.io/qr?text="&ENCODEURL("https://script.google.com/macros/s/AKfycbwQpzkxOCRP3NYqoeT2iICUn44Z1fFWd3SGrCOmIeLE-uz8Fxp4eBwg-OJKyc6xQgcnDA/exec?id="&B3))
A4: PC 3 | B4: =CONCATENATE("AKL-PC-00",RIGHT(A4,LEN(A4) - (FIND(" ",A4))),"-26") -> AKL-PC-003-26 | C4: IB3OM4O | D4: i5-2500 | E4: 8 GB | F4: 500 GB | G4: WINDOWS 10 | H4: LOGITECH | I4: LOGITECH | J4: LG 14 INC | K4: SIMBADDA | L4: BAIK | M4: GIGABYTE H61M-DS2 | T4: =IMAGE("https://quickchart.io/qr?text="&ENCODEURL("https://script.google.com/macros/s/AKfycbwQpzkxOCRP3NYqoeT2iICUn44Z1fFWd3SGrCOmIeLE-uz8Fxp4eBwg-OJKyc6xQgcnDA/exec?id="&B4))
A5: PC 4 | B5: =CONCATENATE("AKL-PC-00",RIGHT(A5,LEN(A5) - (FIND(" ",A5))),"-26") -> AKL-PC-004-26 | C5: OIB6OC | D5: i3-4170 | E5: 4 GB | F5: 128 GB | G5: WINDOWS 10 | H5: LOGITECH | I5: LOGITECH | J5: LG 14 INC | K5: SIMBADDA | L5: BAIK | M5: GIGABYTE H81M-DS2 | T5: =IMAGE("https://quickchart.io/qr?text="&ENCODEURL("https://script.google.com/macros/s/AKfycbwQpzkxOCRP3NYqoeT2iICUn44Z1fFWd3SGrCOmIeLE-uz8Fxp4eBwg-OJKyc6xQgcnDA/exec?id="&B5))
A6: PC 5 | B6: =CONCATENATE("AKL-PC-00",RIGHT(A6,LEN(A6) - (FIND(" ",A6))),"-26") -> AKL-PC-005-26 | C6: - | D6: - | E6: - | F6: - | G6: - | H6: LOGITECH | I6: LOGITECH | J6: LG 14 INC | K6: SIMBADDA | L6: GUDANG | M6: - | T6: =IMAGE("https://quickchart.io/qr?text="&ENCODEURL("https://script.google.com/macros/s/AKfycbwQpzkxOCRP3NYqoeT2iICUn44Z1fFWd3SGrCOmIeLE-uz8Fxp4eBwg-OJKyc6xQgcnDA/exec?id="&B6))
A7: PC 6 | B7: =CONCATENATE("AKL-PC-00",RIGHT(A7,LEN(A7) - (FIND(" ",A7))),"-26") -> AKL-PC-006-26 | C7: WINDOWS-VOVJ8C4 | D7: INTEL CORE i5-2500 | E7: 8 GB | F7: SSD 500 GB | G7: WINDOWS 10 | H7: LOGITECH | I7: LOGITECH | J7: LG 14 INC | K7: SIMBADDA | L7: BAIK | M7: GIGABYTE TECNOLOGY H61M-D52 | T7: =IMAGE("https://quickchart.io/qr?text="&ENCODEURL("https://script.google.com/macros/s/AKfycbwQpzkxOCRP3NYqoeT2iICUn44Z1fFWd3SGrCOmIeLE-uz8Fxp4eBwg-OJKyc6xQgcnDA/exec?id="&B7))
A8: PC 7 | B8: =CONCATENATE("AKL-PC-00",RIGHT(A8,LEN(A8) - (FIND(" ",A8))),"-26") -> AKL-PC-007-26 | C8: DEKSTOP-LMHKAKP | D8: INTEL CORE i5-2400 | E8: 8 GB | F8: 596 GB | G8: WINDOWS 10 | H8: LOGITECH | I8: LOGITECH | J8: LG 14 INC | K8: SIMBADDA | L8: BAIK | M8: GIGABYTE TECNOLOGY H61M-D52 | T8: =IMAGE("https://quickchart.io/qr?text="&ENCODEURL("https://script.google.com/macros/s/AKfycbwQpzkxOCRP3NYqoeT2iICUn44Z1fFWd3SGrCOmIeLE-uz8Fxp4eBwg-OJKyc6xQgcnDA/exec?id="&B8))
A9: PC 8 | B9: =CONCATENATE("AKL-PC-00",RIGHT(A9,LEN(A9) - (FIND(" ",A9))),"-26") -> AKL-PC-008-26 | C9: DEKSTOP-A2VCCU5 | D9: INTEL CORE i5-2400 | E9: 8 GB | F9: 477 GB | G9: WINDOWS 10 | H9: LOGITECH | I9: LOGITECH | J9: LG 14 INC | K9: SIMBADDA | L9: BAIK | M9: GIGABYTE TECNOLOGY H61M-D52 | T9: =IMAGE("https://quickchart.io/qr?text="&ENCODEURL("https://script.google.com/macros/s/AKfycbwQpzkxOCRP3NYqoeT2iICUn44Z1fFWd3SGrCOmIeLE-uz8Fxp4eBwg-OJKyc6xQgcnDA/exec?id="&B9))
A10: PC 9 | B10: =CONCATENATE("AKL-PC-00",RIGHT(A10,LEN(A10) - (FIND(" ",A10))),"-26") -> AKL-PC-009-26 | C10: - | D10: INTEL CORE i5-3470 | E10: 4 GB | F10: 128 GB | G10: WINDOWS 10 | H10: LOGITECH | I10: LOGITECH | J10: LG 14 INC | K10: SIMBADDA | L10: WINDOWS RUSAK | M10: ASUS H61M-K | T10: =IMAGE("https://quickchart.io/qr?text="&ENCODEURL("https://script.google.com/macros/s/AKfycbwQpzkxOCRP3NYqoeT2iICUn44Z1fFWd3SGrCOmIeLE-uz8Fxp4eBwg-OJKyc6xQgcnDA/exec?id="&B10))
A11: PC 10 | B11: =CONCATENATE("AKL-PC-00",RIGHT(A11,LEN(A11) - (FIND(" ",A11))),"-26") -> AKL-PC-0010-26 | C11: - | D11: - | E11: - | F11: - | G11: - | H11: LOGITECH | I11: LOGITECH | J11: LG 14 INC | K11: - | L11: GUDANG | M11: - | T11: =IMAGE("https://quickchart.io/qr?text="&ENCODEURL("https://script.google.com/macros/s/AKfycbwQpzkxOCRP3NYqoeT2iICUn44Z1fFWd3SGrCOmIeLE-uz8Fxp4eBwg-OJKyc6xQgcnDA/exec?id="&B11))
A12: PC 11 | B12: =CONCATENATE("AKL-PC-00",RIGHT(A12,LEN(A12) - (FIND(" ",A12))),"-26") -> AKL-PC-0011-26 | C12: - | D12: - | E12: - | F12: - | G12: - | H12: LOGITECH | I12: LOGITECH | J12: VARRO 19 INC | K12: - | L12: GUDANG | M12: - | T12: =IMAGE("https://quickchart.io/qr?text="&ENCODEURL("https://script.google.com/macros/s/AKfycbwQpzkxOCRP3NYqoeT2iICUn44Z1fFWd3SGrCOmIeLE-uz8Fxp4eBwg-OJKyc6xQgcnDA/exec?id="&B12))
A13: PC 12 | B13: =CONCATENATE("AKL-PC-00",RIGHT(A13,LEN(A13) - (FIND(" ",A13))),"-26") -> AKL-PC-0012-26 | C13: ECLM93S | D13: i5-3470 | E13: 8 GB | F13: 128 GB | G13: WINDOWS 10 | H13: LOGITECH | I13: LOGITECH | J13: ADVAN 14 INC | K13: SIMBADDA | L13: BAIK | M13: ASUS H61M-K | T13: =IMAGE("https://quickchart.io/qr?text="&ENCODEURL("https://script.google.com/macros/s/AKfycbwQpzkxOCRP3NYqoeT2iICUn44Z1fFWd3SGrCOmIeLE-uz8Fxp4eBwg-OJKyc6xQgcnDA/exec?id="&B13))
... A21: PC 20 | B21: =CONCATENATE("AKL-PC-00",RIGHT(A21,LEN(A21) - (FIND(" ",A21))),"-26") -> AKL-PC-0020-26 | C21: ADVAN | D21: INTEL CORE i3-2120 | E21: 4 GB | F21: 477 GB | G21: WINDOWS 10 | H21: LOGITECH | I21: LOGITECH | J21: ADVAN 14 INC | K21: SAMSUNG | L21: BAIK | M21: BIOSTAR H61MLV3 | T21: =IMAGE("https://quickchart.io/qr?text="&ENCODEURL("https://script.google.com/macros/s/AKfycbwQpzkxOCRP3NYqoeT2iICUn44Z1fFWd3SGrCOmIeLE-uz8Fxp4eBwg-OJKyc6xQgcnDA/exec?id="&B21))
A22: PC 21 | B22: =CONCATENATE("AKL-PC-00",RIGHT(A22,LEN(A22) - (FIND(" ",A22))),"-26") -> AKL-PC-0021-26 | C22: DEKSTOP-NBN1FBK | D22: INTEL CORE i3-2120 | E22: 4 GB | F22: 477 GB | G22: WINDOWS 10 | H22: LOGITECH | I22: LOGITECH | J22: LG 14 INC | K22: POWER LOGIC | L22: BAIK | T22: =IMAGE("https://quickchart.io/qr?text="&ENCODEURL("https://script.google.com/macros/s/AKfycbwQpzkxOCRP3NYqoeT2iICUn44Z1fFWd3SGrCOmIeLE-uz8Fxp4eBwg-OJKyc6xQgcnDA/exec?id="&B22))
A23: PC 22 | B23: =CONCATENATE("AKL-PC-00",RIGHT(A23,LEN(A23) - (FIND(" ",A23))),"-26") -> AKL-PC-0022-26 | C23: 2L7VPK2 | D23: i3-4170 | E23: 6 GB | F23: 128 GB | G23: WINDOWS 10 | H23: LOGITECH | I23: LOGITECH | J23: LG 19 INC | K23: SIMBADDA | L23: BAIK | M23: GIGABYTE H81M-DS2 | T23: =IMAGE("https://quickchart.io/qr?text="&ENCODEURL("https://script.google.com/macros/s/AKfycbwQpzkxOCRP3NYqoeT2iICUn44Z1fFWd3SGrCOmIeLE-uz8Fxp4eBwg-OJKyc6xQgcnDA/exec?id="&B23))
A24: PC 23 | B24: =CONCATENATE("AKL-PC-00",RIGHT(A24,LEN(A24) - (FIND(" ",A24))),"-26") -> AKL-PC-0023-26 | C24: DEKSTOP-SF04I1F | D24: INTEL CORE i3-4170 | E24: 4 GB | F24: 466 GB | G24: WINDOWS 10 | H24: LOGITECH | I24: LOGITECH | J24: LG 14 INC | K24: SIMBADDA | L24: BAIK | M24: GIGABYTE TECNOLOGY H81M-DS2 | T24: =IMAGE("https://quickchart.io/qr?text="&ENCODEURL("https://script.google.com/macros/s/AKfycbwQpzkxOCRP3NYqoeT2iICUn44Z1fFWd3SGrCOmIeLE-uz8Fxp4eBwg-OJKyc6xQgcnDA/exec?id="&B24))
A25: PC 24 | B25: =CONCATENATE("AKL-PC-00",RIGHT(A25,LEN(A25) - (FIND(" ",A25))),"-26") -> AKL-PC-0024-26 | C25: DESKTOP-IV3IMA86 | D25: INTEL CORE i3-4170 | E25: 4 GB | F25: 477 GB | G25: WINDOWS 10 | H25: LOGITECH | I25: LOGITECH | J25: LENOVO 19 INC | K25: SIMBADDA | L25: BAIK | M25: GIGABYTE TECNOLOGY H81M-DS3 | T25: =IMAGE("https://quickchart.io/qr?text="&ENCODEURL("https://script.google.com/macros/s/AKfycbwQpzkxOCRP3NYqoeT2iICUn44Z1fFWd3SGrCOmIeLE-uz8Fxp4eBwg-OJKyc6xQgcnDA/exec?id="&B25))
